Workbook

Sheet 基本信息统计
A1: 基本信息统计
A2: 176份原始答卷；主分析122份。各题有效分母另列。
A4: 样本流程 | B4: 人数
A5: 原始回收 | B5: =COUNTA(#REF!) -> 1 | I5: 选项 | J5: 人数
A6: 筛选结束 | B6: =COUNTIFS(数据清洗!$D$2:$D$177,0) -> 1 | I6: 18–22岁 | J6: =基本信息统计!C16 -> 35
A7: 筛选后记录 | B7: =COUNTIFS(数据清洗!$D$2:$D$177,1) -> 175 | I7: 23–29岁 | J7: =基本信息统计!C15 -> 55
A8: 重复文本群暂不纳入 | B8: =COUNTIFS(数据清洗!$D$2:$D$177,1,数据清洗!$Q$2:$Q$177,1) -> 53 | I8: 30–39岁 | J8: =基本信息统计!C14 -> 26
A9: 主分析样本 | B9: =COUNTIFS(数据清洗!$E$2:$E$177,1) -> 122 | I9: 40岁及以上 | J9: =基本信息统计!C18 -> 3
I10: 不愿透露 | J10: =基本信息统计!C17 -> 3
A11: 提交时间：2026-09-25 07:16:40至14:19:23（原导出时区未注明）。主样本用时128–2796秒，中位312.5秒。
A13: 题目/范围 | B13: 选项 | C13: 人数 n | D13: 有效分母 N | E13: 比例 n/N | F13: 口径
A14: 年龄 | B14: 30–39岁 | C14: =COUNTIFS(数据清洗!$E$2:$E$177,1,数据清洗!$G$2:$G$177,"30–39岁") -> 26 | D14: =COUNTIFS(数据清洗!$E$2:$E$177,1) -> 122 | E14: =IF(D14=0,"",C14/D14) -> 0.21311475 | F14: 主分析样本
A15: 年龄 | B15: 23–29岁 | C15: =COUNTIFS(数据清洗!$E$2:$E$177,1,数据清洗!$G$2:$G$177,"23–29岁") -> 55 | D15: =COUNTIFS(数据清洗!$E$2:$E$177,1) -> 122 | E15: =IF(D15=0,"",C15/D15) -> 0.45081967 | F15: 主分析样本
A16: 年龄 | B16: 18–22岁 | C16: =COUNTIFS(数据清洗!$E$2:$E$177,1,数据清洗!$G$2:$G$177,"18–22岁") -> 35 | D16: =COUNTIFS(数据清洗!$E$2:$E$177,1) -> 122 | E16: =IF(D16=0,"",C16/D16) -> 0.28688525 | F16: 主分析样本
A17: 年龄 | B17: 不愿透露 | C17: =COUNTIFS(数据清洗!$E$2:$E$177,1,数据清洗!$G$2:$G$177,"不愿透露") -> 3 | D17: =COUNTIFS(数据清洗!$E$2:$E$177,1) -> 122 | E17: =IF(D17=0,"",C17/D17) -> 0.024590164 | F17: 主分析样本
A18: 年龄 | B18: 40岁及以上 | C18: =COUNTIFS(数据清洗!$E$2:$E$177,1,数据清洗!$G$2:$G$177,"40岁及以上") -> 3 | D18: =COUNTIFS(数据清洗!$E$2:$E$177,1) -> 122 | E18: =IF(D18=0,"",C18/D18) -> 0.024590164 | F18: 主分析样本
A19: 性别 | B19: 女 | C19: =COUNTIFS(数据清洗!$E$2:$E$177,1,数据清洗!$H$2:$H$177,"女") -> 40 | D19: =COUNTIFS(数据清洗!$E$2:$E$177,1) -> 122 | E19: =IF(D19=0,"",C19/D19) -> 0.32786885 | F19: 主分析样本
A20: 性别 | B20: 男 | C20: =COUNTIFS(数据清洗!$E$2:$E$177,1,数据清洗!$H$2:$H$177,"男") -> 75 | D20: =COUNTIFS(数据清洗!$E$2:$E$177,1) -> 122 | E20: =IF(D20=0,"",C20/D20) -> 0.6147541 | F20: 主分析样本
A21: 性别 | B21: 其他 | C21: =COUNTIFS(数据清洗!$E$2:$E$177,1,数据清洗!$H$2:$H$177,"其他") -> 4 | D21: =COUNTIFS(数据清洗!$E$2:$E$177,1) -> 122 | E21: =IF(D21=0,"",C21/D21) -> 0.032786885 | F21: 主分析样本
A22: 性别 | B22: 不愿透露 | C22: =COUNTIFS(数据清洗!$E$2:$E$177,1,数据清洗!$H$2:$H$177,"不愿透露") -> 3 | D22: =COUNTIFS(数据清洗!$E$2:$E$177,1) -> 122 | E22: =IF(D22=0,"",C22/D22) -> 0.024590164 | F22: 主分析样本
A23: 学历 | B23: 硕士研究生及以上 | C23: =COUNTIFS(数据清洗!$E$2:$E$177,1,数据清洗!$I$2:$I$177,"硕士研究生及以上") -> 4 | D23: =COUNTIFS(数据清洗!$E$2:$E$177,1) -> 122 | E23: =IF(D23=0,"",C23/D23) -> 0.032786885 | F23: 主分析样本
A24: 学历 | B24: 本科 | C24: =COUNTIFS(数据清洗!$E$2:$E$177,1,数据清洗!$I$2:$I$177,"本科") -> 78 | D24: =COUNTIFS(数据清洗!$E$2:$E$177,1) -> 122 | E24: =IF(D24=0,"",C24/D24) -> 0.63934426 | F24: 主分析样本
A25: 学历 | B25: 大专 | C25: =COUNTIFS(数据清洗!$E$2:$E$177,1,数据清洗!$I$2:$I$177,"大专") -> 25 | D25: =COUNTIFS(数据清洗!$E$2:$E$177,1) -> 122 | E25: =IF(D25=0,"",C25/D25) -> 0.20491803 | F25: 主分析样本
A26: 学历 | B26: 不愿透露 | C26: =COUNTIFS(数据清洗!$E$2:$E$177,1,数据清洗!$I$2:$I$177,"不愿透露") -> 2 | D26: =COUNTIFS(数据清洗!$E$2:$E$177,1) -> 122 | E26: =IF(D26=0,"",C26/D26) -> 0.016393443 | F26: 主分析样本
A27: 学历 | B27: 高中／中专／职高／技校 | C27: =COUNTIFS(数据清洗!$E$2:$E$177,1,数据清洗!$I$2:$I$177,"高中／中专／职高／技校") -> 12 | D27: =COUNTIFS(数据清洗!$E$2:$E$177,1) -> 122 | E27: =IF(D27=0,"",C27/D27) -> 0.098360656 | F27: 主分析样本
A28: 学历 | B28: 初中及以下 | C28: =COUNTIFS(数据清洗!$E$2:$E$177,1,数据清洗!$I$2:$I$177,"初中及以下") -> 1 | D28: =COUNTIFS(数据清洗!$E$2:$E$177,1) -> 122 | E28: =IF(D28=0,"",C28/D28) -> 0.0081967213 | F28: 主分析样本
A29: B站频率 | B29: 从未使用过B站 | C29: =COUNTIFS(数据清洗!$E$2:$E$177,1,数据清洗!$J$2:$J$177,"从未使用过B站") -> 5 | D29: =COUNTIFS(数据清洗!$E$2:$E$177,1) -> 122 | E29: =IF(D29=0,"",C29/D29) -> 0.040983607 | F29: 主分析样本
A30: B站频率 | B30: 每周1–2天 | C30: =COUNTIFS(数据清洗!$E$2:$E$177,1,数据清洗!$J$2:$J$177,"每周1–2天") -> 29 | D30: =COUNTIFS(数据清洗!$E$2:$E$177,1) -> 122 | E30: =IF(D30=0,"",C30/D30) -> 0.23770492 | F30: 主分析样本
A31: B站频率 | B31: 几乎每天 | C31: =COUNTIFS(数据清洗!$E$2:$E$177,1,数据清洗!$J$2:$J$177,"几乎每天") -> 39 | D31: =COUNTIFS(数据清洗!$E$2:$E$177,1) -> 122 | E31: =IF(D31=0,"",C31/D31) -> 0.31967213 | F31: 主分析样本
A32: B站频率 | B32: 少于每周1天 | C32: =COUNTIFS(数据清洗!$E$2:$E$177,1,数据清洗!$J$2:$J$177,"少于每周1天") -> 13 | D32: =COUNTIFS(数据清洗!$E$2:$E$177,1) -> 122 | E32: =IF(D32=0,"",C32/D32) -> 0.10655738 | F32: 主分析样本
A33: B站频率 | B33: 每周3–6天 | C33: =COUNTIFS(数据清洗!$E$2:$E$177,1,数据清洗!$J$2:$J$177,"每周3–6天") -> 34 | D33: =COUNTIFS(数据清洗!$E$2:$E$177,1) -> 122 | E33: =IF(D33=0,"",C33/D33) -> 0.27868852 | F33: 主分析样本
A34: B站频率 | B34: 过去3个月没有使用过 | C34: =COUNTIFS(数据清洗!$E$2:$E$177,1,数据清洗!$J$2:$J$177,"过去3个月没有使用过") -> 2 | D34: =COUNTIFS(数据清洗!$E$2:$E$177,1) -> 122 | E34: =IF(D34=0,"",C34/D34) -> 0.016393443 | F34: 主分析样本

Sheet 购买及闲置行为
A1: 购买及闲置行为
A2: 购买、闲置单选按主样本统计；Q8/9仅购买者；Q11排除9份与明确未尝试冲突的记录。多选百分比可超过100%。
A5: 题目/范围 | B5: 选项 | C5: 人数 n | D5: 有效分母 N | E5: 比例 n/N | F5: 口径 | I5: 选项 | J5: 人数
A6: 购买次数 | B6: 1–2次 | C6: =COUNTIFS(数据清洗!$E$2:$E$177,1,数据清洗!$K$2:$K$177,"1–2次") -> 33 | D6: =COUNTIFS(数据清洗!$E$2:$E$177,1) -> 122 | E6: =IF(D6=0,"",C6/D6) -> 0.2704918 | F6: 主分析样本 | I6: 有 | J6: =购买及闲置行为!C12 -> 58
A7: 购买次数 | B7: 3–5次 | C7: =COUNTIFS(数据清洗!$E$2:$E$177,1,数据清洗!$K$2:$K$177,"3–5次") -> 38 | D7: =COUNTIFS(数据清洗!$E$2:$E$177,1) -> 122 | E7: =IF(D7=0,"",C7/D7) -> 0.31147541 | F7: 主分析样本 | I7: 没有 | J7: =购买及闲置行为!C13 -> 43
A8: 购买次数 | B8: 0次 | C8: =COUNTIFS(数据清洗!$E$2:$E$177,1,数据清洗!$K$2:$K$177,"0次") -> 28 | D8: =COUNTIFS(数据清洗!$E$2:$E$177,1) -> 122 | E8: =IF(D8=0,"",C8/D8) -> 0.2295082 | F8: 主分析样本 | I8: 不确定 | J8: =购买及闲置行为!C14 -> 21
A9: 购买次数 | B9: 6–11次 | C9: =COUNTIFS(数据清洗!$E$2:$E$177,1,数据清洗!$K$2:$K$177,"6–11次") -> 20 | D9: =COUNTIFS(数据清洗!$E$2:$E$177,1) -> 122 | E9: =IF(D9=0,"",C9/D9) -> 0.16393443 | F9: 主分析样本
A10: 购买次数 | B10: 12次及以上 | C10: =COUNTIFS(数据清洗!$E$2:$E$177,1,数据清洗!$K$2:$K$177,"12次及以上") -> 2 | D10: =COUNTIFS(数据清洗!$E$2:$E$177,1) -> 122 | E10: =IF(D10=0,"",C10/D10) -> 0.016393443 | F10: 主分析样本
A11: 购买次数 | B11: 买过，但记不清次数 | C11: =COUNTIFS(数据清洗!$E$2:$E$177,1,数据清洗!$K$2:$K$177,"买过，但记不清次数") -> 1 | D11: =COUNTIFS(数据清洗!$E$2:$E$177,1) -> 122 | E11: =IF(D11=0,"",C11/D11) -> 0.0081967213 | F11: 主分析样本
A12: 闲置情况 | B12: 有 | C12: =COUNTIFS(数据清洗!$E$2:$E$177,1,数据清洗!$M$2:$M$177,"有") -> 58 | D12: =COUNTIFS(数据清洗!$E$2:$E$177,1) -> 122 | E12: =IF(D12=0,"",C12/D12) -> 0.47540984 | F12: 主分析样本
A13: 闲置情况 | B13: 没有 | C13: =COUNTIFS(数据清洗!$E$2:$E$177,1,数据清洗!$M$2:$M$177,"没有") -> 43 | D13: =COUNTIFS(数据清洗!$E$2:$E$177,1) -> 122 | E13: =IF(D13=0,"",C13/D13) -> 0.35245902 | F13: 主分析样本
A14: 闲置情况 | B14: 不确定 | C14: =COUNTIFS(数据清洗!$E$2:$E$177,1,数据清洗!$M$2:$M$177,"不确定") -> 21 | D14: =COUNTIFS(数据清洗!$E$2:$E$177,1) -> 122 | E14: =IF(D14=0,"",C14/D14) -> 0.17213115 | F14: 主分析样本
A15: Q8 购买类型（多选） | B15: 亚克力立牌／挂件等 | C15: =COUNTIFS(数据清洗!$E$2:$E$177,1,数据清洗!$Y$2:$Y$177,1,数据清洗!$Z$2:$Z$177,1) -> 45 | D15: =COUNTIFS(数据清洗!$E$2:$E$177,1,数据清洗!$Y$2:$Y$177,1) -> 93 | E15: =IF(D15=0,"",C15/D15) -> 0.48387097 | F15: Q8购买类型；限近期购买且无互斥冲突
A16: Q8 购买类型（多选） | B16: 其他，请注明: | C16: =COUNTIFS(数据清洗!$E$2:$E$177,1,数据清洗!$Y$2:$Y$177,1,数据清洗!$AA$2:$AA$177,1) -> 1 | D16: =COUNTIFS(数据清洗!$E$2:$E$177,1,数据清洗!$Y$2:$Y$177,1) -> 93 | E16: =IF(D16=0,"",C16/D16) -> 0.010752688 | F16: Q8购买类型；限近期购买且无互斥冲突
A17: Q8 购买类型（多选） | B17: 卡片／拍立得／纸类周边 | C17: =COUNTIFS(数据清洗!$E$2:$E$177,1,数据清洗!$Y$2:$Y$177,1,数据清洗!$AB$2:$AB$177,1) -> 38 | D17: =COUNTIFS(数据清洗!$E$2:$E$177,1,数据清洗!$Y$2:$Y$177,1) -> 93 | E17: =IF(D17=0,"",C17/D17) -> 0.40860215 | F17: Q8购买类型；限近期购买且无互斥冲突
A18: Q8 购买类型（多选） | B18: 徽章／吧唧 | C18: =COUNTIFS(数据清洗!$E$2:$E$177,1,数据清洗!$Y$2:$Y$177,1,数据清洗!$AC$2:$AC$177,1) -> 36 | D18: =COUNTIFS(数据清洗!$E$2:$E$177,1,数据清洗!$Y$2:$Y$177,1) -> 93 | E18: =IF(D18=0,"",C18/D18) -> 0.38709677 | F18: Q8购买类型；限近期购买且无互斥冲突
A19: Q8 购买类型（多选） | B19: 手办／模型 | C19: =COUNTIFS(数据清洗!$E$2:$E$177,1,数据清洗!$Y$2:$Y$177,1,数据清洗!$AD$2:$AD$177,1) -> 55 | D19: =COUNTIFS(数据清洗!$E$2:$E$177,1,数据清洗!$Y$2:$Y$177,1) -> 93 | E19: =IF(D19=0,"",C19/D19) -> 0.59139785 | F19: Q8购买类型；限近期购买且无互斥冲突
A20: Q8 购买类型（多选） | B20: 毛绒玩具／棉花娃娃 | C20: =COUNTIFS(数据清洗!$E$2:$E$177,1,数据清洗!$Y$2:$Y$177,1,数据清洗!$AE$2:$AE$177,1) -> 30 | D20: =COUNTIFS(数据清洗!$E$2:$E$177,1,数据清洗!$Y$2:$Y$177,1) -> 93 | E20: =IF(D20=0,"",C20/D20) -> 0.32258065 | F20: Q8购买类型；限近期购买且无互斥冲突
A21: Q8 购买类型（多选） | B21: 记不清 | C21: =COUNTIFS(数据清洗!$E$2:$E$177,1,数据清洗!$Y$2:$Y$177,1,数据清洗!$AF$2:$AF$177,1) -> 0 | D21: =COUNTIFS(数据清洗!$E$2:$E$177,1,数据清洗!$Y$2:$Y$177,1) -> 93 | E21: =IF(D21=0,"",C21/D21) -> 0 | F21: Q8购买类型；限近期购买且无互斥冲突
A22: Q9 购买渠道（多选） | B22: B站会员购市集 | C22: =COUNTIFS(数据清洗!$E$2:$E$177,1,数据清洗!$AG$2:$AG$177,1,数据清洗!$AH$2:$AH$177,1) -> 41 | D22: =COUNTIFS(数据清洗!$E$2:$E$177,1,数据清洗!$AG$2:$AG$177,1) -> 93 | E22: =IF(D22=0,"",C22/D22) -> 0.44086022 | F22: Q9购买渠道；限近期购买且无互斥冲突
A23: Q9 购买渠道（多选） | B23: B站会员购（不含市集） | C23: =COUNTIFS(数据清洗!$E$2:$E$177,1,数据清洗!$AG$2:$AG$177,1,数据清洗!$AI$2:$AI$177,1) -> 38 | D23: =COUNTIFS(数据清洗!$E$2:$E$177,1,数据清洗!$AG$2:$AG$177,1) -> 93 | E23: =IF(D23=0,"",C23/D23) -> 0.40860215 | F23: Q9购买渠道；限近期购买且无互斥冲突
A24: Q9 购买渠道（多选） | B24: QQ群／QQ同好 | C24: =COUNTIFS(数据清洗!$E$2:$E$177,1,数据清洗!$AG$2:$AG$177,1,数据清洗!$AJ$2:$AJ$177,1) -> 18 | D24: =COUNTIFS(数据清洗!$E$2:$E$177,1,数据清洗!$AG$2:$AG$177,1) -> 93 | E24: =IF(D24=0,"",C24/D24) -> 0.19354839 | F24: Q9购买渠道；限近期购买且无互斥冲突
A25: Q9 购买渠道（多选） | B25: 其他线上渠道，如淘宝、品牌官方店等 | C25: =COUNTIFS(数据清洗!$E$2:$E$177,1,数据清洗!$AG$2:$AG$177,1,数据清洗!$AK$2:$AK$177,1) -> 44 | D25: =COUNTIFS(数据清洗!$E$2:$E$177,1,数据清洗!$AG$2:$AG$177,1) -> 93 | E25: =IF(D25=0,"",C25/D25) -> 0.47311828 | F25: Q9购买渠道；限近期购买且无互斥冲突
A26: Q9 购买渠道（多选） | B26: 其他，请注明: | C26: =COUNTIFS(数据清洗!$E$2:$E$177,1,数据清洗!$AG$2:$AG$177,1,数据清洗!$AL$2:$AL$177,1) -> 3 | D26: =COUNTIFS(数据清洗!$E$2:$E$177,1,数据清洗!$AG$2:$AG$177,1) -> 93 | E26: =IF(D26=0,"",C26/D26) -> 0.032258065 | F26: Q9购买渠道；限近期购买且无互斥冲突
A27: Q9 购买渠道（多选） | B27: 微信群／微信同好 | C27: =COUNTIFS(数据清洗!$E$2:$E$177,1,数据清洗!$AG$2:$AG$177,1,数据清洗!$AM$2:$AM$177,1) -> 26 | D27: =COUNTIFS(数据清洗!$E$2:$E$177,1,数据清洗!$AG$2:$AG$177,1) -> 93 | E27: =IF(D27=0,"",C27/D27) -> 0.27956989 | F27: Q9购买渠道；限近期购买且无互斥冲突
A28: Q9 购买渠道（多选） | B28: 线下门店／展会／同好活动 | C28: =COUNTIFS(数据清洗!$E$2:$E$177,1,数据清洗!$AG$2:$AG$177,1,数据清洗!$AN$2:$AN$177,1) -> 18 | D28: =COUNTIFS(数据清洗!$E$2:$E$177,1,数据清洗!$AG$2:$AG$177,1) -> 93 | E28: =IF(D28=0,"",C28/D28) -> 0.19354839 | F28: Q9购买渠道；限近期购买且无互斥冲突 | I28: 选项 | J28: 人数
A29: Q9 购买渠道（多选） | B29: 记不清 | C29: =COUNTIFS(数据清洗!$E$2:$E$177,1,数据清洗!$AG$2:$AG$177,1,数据清洗!$AO$2:$AO$177,1) -> 0 | D29: =COUNTIFS(数据清洗!$E$2:$E$177,1,数据清洗!$AG$2:$AG$177,1) -> 93 | E29: =IF(D29=0,"",C29/D29) -> 0 | F29: Q9购买渠道；限近期购买且无互斥冲突 | I29: 尝试出售 | J29: =购买及闲置行为!C34 -> 31
A30: Q9 购买渠道（多选） | B30: 闲鱼 | C30: =COUNTIFS(数据清洗!$E$2:$E$177,1,数据清洗!$AG$2:$AG$177,1,数据清洗!$AP$2:$AP$177,1) -> 49 | D30: =COUNTIFS(数据清洗!$E$2:$E$177,1,数据清洗!$AG$2:$AG$177,1) -> 93 | E30: =IF(D30=0,"",C30/D30) -> 0.52688172 | F30: Q9购买渠道；限近期购买且无互斥冲突 | I30: 尝试交换 | J30: =购买及闲置行为!C33 -> 26
A31: Q11 处理方式（多选） | B31: 丢弃／回收 | C31: =COUNTIFS(数据清洗!$E$2:$E$177,1,数据清洗!$AQ$2:$AQ$177,1,数据清洗!$AR$2:$AR$177,1) -> 5 | D31: =COUNTIFS(数据清洗!$E$2:$E$177,1,数据清洗!$AQ$2:$AQ$177,1) -> 49 | E31: =IF(D31=0,"",C31/D31) -> 0.10204082 | F31: Q11处理方式；限Q10有闲置且与明确均未尝试不冲突 | I31: 继续保留 | J31: =购买及闲置行为!C35 -> 18
A32: Q11 处理方式（多选） | B32: 其他，请注明: | C32: =COUNTIFS(数据清洗!$E$2:$E$177,1,数据清洗!$AQ$2:$AQ$177,1,数据清洗!$AS$2:$AS$177,1) -> 0 | D32: =COUNTIFS(数据清洗!$E$2:$E$177,1,数据清洗!$AQ$2:$AQ$177,1) -> 49 | E32: =IF(D32=0,"",C32/D32) -> 0 | F32: Q11处理方式；限Q10有闲置且与明确均未尝试不冲突 | I32: 赠送 | J32: =购买及闲置行为!C36 -> 11
A33: Q11 处理方式（多选） | B33: 尝试交换，包括发布换物信息或联系交换对象 | C33: =COUNTIFS(数据清洗!$E$2:$E$177,1,数据清洗!$AQ$2:$AQ$177,1,数据清洗!$AT$2:$AT$177,1) -> 26 | D33: =COUNTIFS(数据清洗!$E$2:$E$177,1,数据清洗!$AQ$2:$AQ$177,1) -> 49 | E33: =IF(D33=0,"",C33/D33) -> 0.53061224 | F33: Q11处理方式；限Q10有闲置且与明确均未尝试不冲突 | I33: 丢弃／回收 | J33: =购买及闲置行为!C31 -> 5
A34: Q11 处理方式（多选） | B34: 尝试出售，包括发布信息、询价或联系买家 | C34: =COUNTIFS(数据清洗!$E$2:$E$177,1,数据清洗!$AQ$2:$AQ$177,1,数据清洗!$AU$2:$AU$177,1) -> 31 | D34: =COUNTIFS(数据清洗!$E$2:$E$177,1,数据清洗!$AQ$2:$AQ$177,1) -> 49 | E34: =IF(D34=0,"",C34/D34) -> 0.63265306 | F34: Q11处理方式；限Q10有闲置且与明确均未尝试不冲突
A35: Q11 处理方式（多选） | B35: 继续保留，尚未采取处理行动 | C35: =COUNTIFS(数据清洗!$E$2:$E$177,1,数据清洗!$AQ$2:$AQ$177,1,数据清洗!$AV$2:$AV$177,1) -> 18 | D35: =COUNTIFS(数据清洗!$E$2:$E$177,1,数据清洗!$AQ$2:$AQ$177,1) -> 49 | E35: =IF(D35=0,"",C35/D35) -> 0.36734694 | F35: Q11处理方式；限Q10有闲置且与明确均未尝试不冲突
A36: Q11 处理方式（多选） | B36: 赠送 | C36: =COUNTIFS(数据清洗!$E$2:$E$177,1,数据清洗!$AQ$2:$AQ$177,1,数据清洗!$AW$2:$AW$177,1) -> 11 | D36: =COUNTIFS(数据清洗!$E$2:$E$177,1,数据清洗!$AQ$2:$AQ$177,1) -> 49 | E36: =IF(D36=0,"",C36/D36) -> 0.2244898 | F36: Q11处理方式；限Q10有闲置且与明确均未尝试不冲突

Sheet 交易痛点
A1: 交易痛点
A2: 出售、交换按Q12可确认的记录分列；另一行为未知。Q14严格可配对子样本仅27份，不能据此推算总体痛点发生率。
A5: 题目/范围 | B5: 选项 | C5: 人数 n | D5: 有效分母 N | E5: 比例 n/N | F5: 口径 | I5: 选项 | J5: 人数
A6: 交易分组 | B6: 交换尝试记录 | C6: =COUNTIFS(数据清洗!$E$2:$E$177,1,数据清洗!$X$2:$X$177,"交换尝试记录") -> 40 | D6: =COUNTIFS(数据清洗!$E$2:$E$177,1) -> 122 | E6: =IF(D6=0,"",C6/D6) -> 0.32786885 | F6: 主分析样本 | I6: 出售尝试记录 | J6: =交易痛点!C7 -> 28
A7: 交易分组 | B7: 出售尝试记录 | C7: =COUNTIFS(数据清洗!$E$2:$E$177,1,数据清洗!$X$2:$X$177,"出售尝试记录") -> 28 | D7: =COUNTIFS(数据清洗!$E$2:$E$177,1) -> 122 | E7: =IF(D7=0,"",C7/D7) -> 0.2295082 | F7: 主分析样本 | I7: 交换尝试记录 | J7: =交易痛点!C6 -> 40
A8: 交易分组 | B8: 无法判断 | C8: =COUNTIFS(数据清洗!$E$2:$E$177,1,数据清洗!$X$2:$X$177,"无法判断") -> 13 | D8: =COUNTIFS(数据清洗!$E$2:$E$177,1) -> 122 | E8: =IF(D8=0,"",C8/D8) -> 0.10655738 | F8: 主分析样本 | I8: 明确均未尝试 | J8: =交易痛点!C9 -> 41
A9: 交易分组 | B9: 明确均未尝试 | C9: =COUNTIFS(数据清洗!$E$2:$E$177,1,数据清洗!$X$2:$X$177,"明确均未尝试") -> 41 | D9: =COUNTIFS(数据清洗!$E$2:$E$177,1) -> 122 | E9: =IF(D9=0,"",C9/D9) -> 0.33606557 | F9: 主分析样本 | I9: 无法判断 | J9: =交易痛点!C8 -> 13
A10: Q13 尝试渠道（多选） | B10: B站会员购市集 | C10: =COUNTIFS(数据清洗!$E$2:$E$177,1,数据清洗!$AX$2:$AX$177,1,数据清洗!$AY$2:$AY$177,1) -> 32 | D10: =COUNTIFS(数据清洗!$E$2:$E$177,1,数据清洗!$AX$2:$AX$177,1) -> 68 | E10: =IF(D10=0,"",C10/D10) -> 0.47058824 | F10: Q13合并渠道；限Q12可确认尝试，不分出售交换
A11: Q13 尝试渠道（多选） | B11: B站其他位置，如动态、评论、私信等 | C11: =COUNTIFS(数据清洗!$E$2:$E$177,1,数据清洗!$AX$2:$AX$177,1,数据清洗!$AZ$2:$AZ$177,1) -> 36 | D11: =COUNTIFS(数据清洗!$E$2:$E$177,1,数据清洗!$AX$2:$AX$177,1) -> 68 | E11: =IF(D11=0,"",C11/D11) -> 0.52941176 | F11: Q13合并渠道；限Q12可确认尝试，不分出售交换
A12: Q13 尝试渠道（多选） | B12: QQ群／QQ同好 | C12: =COUNTIFS(数据清洗!$E$2:$E$177,1,数据清洗!$AX$2:$AX$177,1,数据清洗!$BA$2:$BA$177,1) -> 13 | D12: =COUNTIFS(数据清洗!$E$2:$E$177,1,数据清洗!$AX$2:$AX$177,1) -> 68 | E12: =IF(D12=0,"",C12/D12) -> 0.19117647 | F12: Q13合并渠道；限Q12可确认尝试，不分出售交换
A13: Q13 尝试渠道（多选） | B13: 其他，请注明: | C13: =COUNTIFS(数据清洗!$E$2:$E$177,1,数据清洗!$AX$2:$AX$177,1,数据清洗!$BB$2:$BB$177,1) -> 0 | D13: =COUNTIFS(数据清洗!$E$2:$E$177,1,数据清洗!$AX$2:$AX$177,1) -> 68 | E13: =IF(D13=0,"",C13/D13) -> 0 | F13: Q13合并渠道；限Q12可确认尝试，不分出售交换
A14: Q13 尝试渠道（多选） | B14: 微信群／微信同好 | C14: =COUNTIFS(数据清洗!$E$2:$E$177,1,数据清洗!$AX$2:$AX$177,1,数据清洗!$BC$2:$BC$177,1) -> 28 | D14: =COUNTIFS(数据清洗!$E$2:$E$177,1,数据清洗!$AX$2:$AX$177,1) -> 68 | E14: =IF(D14=0,"",C14/D14) -> 0.41176471 | F14: Q13合并渠道；限Q12可确认尝试，不分出售交换
A15: Q13 尝试渠道（多选） | B15: 线下门店／展会／同好活动 | C15: =COUNTIFS(数据清洗!$E$2:$E$177,1,数据清洗!$AX$2:$AX$177,1,数据清洗!$BD$2:$BD$177,1) -> 17 | D15: =COUNTIFS(数据清洗!$E$2:$E$177,1,数据清洗!$AX$2:$AX$177,1) -> 68 | E15: =IF(D15=0,"",C15/D15) -> 0.25 | F15: Q13合并渠道；限Q12可确认尝试，不分出售交换
A16: Q13 尝试渠道（多选） | B16: 记不清 | C16: =COUNTIFS(数据清洗!$E$2:$E$177,1,数据清洗!$AX$2:$AX$177,1,数据清洗!$BE$2:$BE$177,1) -> 0 | D16: =COUNTIFS(数据清洗!$E$2:$E$177,1,数据清洗!$AX$2:$AX$177,1) -> 68 | E16: =IF(D16=0,"",C16/D16) -> 0 | F16: Q13合并渠道；限Q12可确认尝试，不分出售交换
A17: Q13 尝试渠道（多选） | B17: 闲鱼 | C17: =COUNTIFS(数据清洗!$E$2:$E$177,1,数据清洗!$AX$2:$AX$177,1,数据清洗!$BF$2:$BF$177,1) -> 37 | D17: =COUNTIFS(数据清洗!$E$2:$E$177,1,数据清洗!$AX$2:$AX$177,1) -> 68 | E17: =IF(D17=0,"",C17/D17) -> 0.54411765 | F17: Q13合并渠道；限Q12可确认尝试，不分出售交换
A18: 出售尝试记录痛点 | B18: 付款或发货顺序难以协商 | C18: =COUNTIFS(数据清洗!$E$2:$E$177,1,数据清洗!$BG$2:$BG$177,1,数据清洗!$X$2:$X$177,"出售尝试记录",数据清洗!$BH$2:$BH$177,1) -> 1 | D18: =COUNTIFS(数据清洗!$E$2:$E$177,1,数据清洗!$BG$2:$BG$177,1,数据清洗!$X$2:$X$177,"出售尝试记录") -> 9 | E18: =IF(D18=0,"",C18/D18) -> 0.11111111 | F18: 仅Q12与Q14行可配对、无互斥冲突；小样本探索
A19: 出售尝试记录痛点 | B19: 其他，请注明: | C19: =COUNTIFS(数据清洗!$E$2:$E$177,1,数据清洗!$BG$2:$BG$177,1,数据清洗!$X$2:$X$177,"出售尝试记录",数据清洗!$BI$2:$BI$177,1) -> 0 | D19: =COUNTIFS(数据清洗!$E$2:$E$177,1,数据清洗!$BG$2:$BG$177,1,数据清洗!$X$2:$X$177,"出售尝试记录") -> 9 | E19: =IF(D19=0,"",C19/D19) -> 0 | F19: 仅Q12与Q14行可配对、无互斥冲突；小样本探索
A20: 出售尝试记录痛点 | B20: 对方临时取消或不再回复 | C20: =COUNTIFS(数据清洗!$E$2:$E$177,1,数据清洗!$BG$2:$BG$177,1,数据清洗!$X$2:$X$177,"出售尝试记录",数据清洗!$BJ$2:$BJ$177,1) -> 3 | D20: =COUNTIFS(数据清洗!$E$2:$E$177,1,数据清洗!$BG$2:$BG$177,1,数据清洗!$X$2:$X$177,"出售尝试记录") -> 9 | E20: =IF(D20=0,"",C20/D20) -> 0.33333333 | F20: 仅Q12与Q14行可配对、无互斥冲突；小样本探索
A21: 出售尝试记录痛点 | B21: 对方对我提供的商品信息有疑虑 | C21: =COUNTIFS(数据清洗!$E$2:$E$177,1,数据清洗!$BG$2:$BG$177,1,数据清洗!$X$2:$X$177,"出售尝试记录",数据清洗!$BK$2:$BK$177,1) -> 3 | D21: =COUNTIFS(数据清洗!$E$2:$E$177,1,数据清洗!$BG$2:$BG$177,1,数据清洗!$X$2:$X$177,"出售尝试记录") -> 9 | E21: =IF(D21=0,"",C21/D21) -> 0.33333333 | F21: 仅Q12与Q14行可配对、无互斥冲突；小样本探索
A22: 出售尝试记录痛点 | B22: 没有遇到明显问题 | C22: =COUNTIFS(数据清洗!$E$2:$E$177,1,数据清洗!$BG$2:$BG$177,1,数据清洗!$X$2:$X$177,"出售尝试记录",数据清洗!$BL$2:$BL$177,1) -> 0 | D22: =COUNTIFS(数据清洗!$E$2:$E$177,1,数据清洗!$BG$2:$BG$177,1,数据清洗!$X$2:$X$177,"出售尝试记录") -> 9 | E22: =IF(D22=0,"",C22/D22) -> 0 | F22: 仅Q12与Q14行可配对、无互斥冲突；小样本探索
A23: 出售尝试记录痛点 | B23: 记不清 | C23: =COUNTIFS(数据清洗!$E$2:$E$177,1,数据清洗!$BG$2:$BG$177,1,数据清洗!$X$2:$X$177,"出售尝试记录",数据清洗!$BM$2:$BM$177,1) -> 0 | D23: =COUNTIFS(数据清洗!$E$2:$E$177,1,数据清洗!$BG$2:$BG$177,1,数据清洗!$X$2:$X$177,"出售尝试记录") -> 9 | E23: =IF(D23=0,"",C23/D23) -> 0 | F23: 仅Q12与Q14行可配对、无互斥冲突；小样本探索
A24: 出售尝试记录痛点 | B24: 遇到物流损坏或丢失 | C24: =COUNTIFS(数据清洗!$E$2:$E$177,1,数据清洗!$BG$2:$BG$177,1,数据清洗!$X$2:$X$177,"出售尝试记录",数据清洗!$BN$2:$BN$177,1) -> 1 | D24: =COUNTIFS(数据清洗!$E$2:$E$177,1,数据清洗!$BG$2:$BG$177,1,数据清洗!$X$2:$X$177,"出售尝试记录") -> 9 | E24: =IF(D24=0,"",C24/D24) -> 0.11111111 | F24: 仅Q12与Q14行可配对、无互斥冲突；小样本探索
A25: 出售尝试记录痛点 | B25: 遇到纠纷后难以解决 | C25: =COUNTIFS(数据清洗!$E$2:$E$177,1,数据清洗!$BG$2:$BG$177,1,数据清洗!$X$2:$X$177,"出售尝试记录",数据清洗!$BO$2:$BO$177,1) -> 1 | D25: =COUNTIFS(数据清洗!$E$2:$E$177,1,数据清洗!$BG$2:$BG$177,1,数据清洗!$X$2:$X$177,"出售尝试记录") -> 9 | E25: =IF(D25=0,"",C25/D25) -> 0.11111111 | F25: 仅Q12与Q14行可配对、无互斥冲突；小样本探索
A26: 出售尝试记录痛点 | B26: 难以就价格／补差价达成一致 | C26: =COUNTIFS(数据清洗!$E$2:$E$177,1,数据清洗!$BG$2:$BG$177,1,数据清洗!$X$2:$X$177,"出售尝试记录",数据清洗!$BQ$2:$BQ$177,1) -> 5 | D26: =COUNTIFS(数据清洗!$E$2:$E$177,1,数据清洗!$BG$2:$BG$177,1,数据清洗!$X$2:$X$177,"出售尝试记录") -> 9 | E26: =IF(D26=0,"",C26/D26) -> 0.55555556 | F26: 仅Q12与Q14行可配对、无互斥冲突；小样本探索
A27: 出售尝试记录痛点 | B27: 难以找到想要我这件周边的人 | C27: =COUNTIFS(数据清洗!$E$2:$E$177,1,数据清洗!$BG$2:$BG$177,1,数据清洗!$X$2:$X$177,"出售尝试记录",数据清洗!$BR$2:$BR$177,1) -> 2 | D27: =COUNTIFS(数据清洗!$E$2:$E$177,1,数据清洗!$BG$2:$BG$177,1,数据清洗!$X$2:$X$177,"出售尝试记录") -> 9 | E27: =IF(D27=0,"",C27/D27) -> 0.22222222 | F27: 仅Q12与Q14行可配对、无互斥冲突；小样本探索
A28: 出售尝试记录痛点 | B28: 需要反复沟通品相、包装等细节 | C28: =COUNTIFS(数据清洗!$E$2:$E$177,1,数据清洗!$BG$2:$BG$177,1,数据清洗!$X$2:$X$177,"出售尝试记录",数据清洗!$BT$2:$BT$177,1) -> 4 | D28: =COUNTIFS(数据清洗!$E$2:$E$177,1,数据清洗!$BG$2:$BG$177,1,数据清洗!$X$2:$X$177,"出售尝试记录") -> 9 | E28: =IF(D28=0,"",C28/D28) -> 0.44444444 | F28: 仅Q12与Q14行可配对、无互斥冲突；小样本探索
A29: 交换尝试记录痛点 | B29: 付款或发货顺序难以协商 | C29: =COUNTIFS(数据清洗!$E$2:$E$177,1,数据清洗!$BG$2:$BG$177,1,数据清洗!$X$2:$X$177,"交换尝试记录",数据清洗!$BH$2:$BH$177,1) -> 7 | D29: =COUNTIFS(数据清洗!$E$2:$E$177,1,数据清洗!$BG$2:$BG$177,1,数据清洗!$X$2:$X$177,"交换尝试记录") -> 18 | E29: =IF(D29=0,"",C29/D29) -> 0.38888889 | F29: 仅Q12与Q14行可配对、无互斥冲突；小样本探索
A30: 交换尝试记录痛点 | B30: 其他，请注明: | C30: =COUNTIFS(数据清洗!$E$2:$E$177,1,数据清洗!$BG$2:$BG$177,1,数据清洗!$X$2:$X$177,"交换尝试记录",数据清洗!$BI$2:$BI$177,1) -> 0 | D30: =COUNTIFS(数据清洗!$E$2:$E$177,1,数据清洗!$BG$2:$BG$177,1,数据清洗!$X$2:$X$177,"交换尝试记录") -> 18 | E30: =IF(D30=0,"",C30/D30) -> 0 | F30: 仅Q12与Q14行可配对、无互斥冲突；小样本探索
A31: 交换尝试记录痛点 | B31: 对方临时取消或不再回复 | C31: =COUNTIFS(数据清洗!$E$2:$E$177,1,数据清洗!$BG$2:$BG$177,1,数据清洗!$X$2:$X$177,"交换尝试记录",数据清洗!$BJ$2:$BJ$177,1) -> 2 | D31: =COUNTIFS(数据清洗!$E$2:$E$177,1,数据清洗!$BG$2:$BG$177,1,数据清洗!$X$2:$X$177,"交换尝试记录") -> 18 | E31: =IF(D31=0,"",C31/D31) -> 0.11111111 | F31: 仅Q12与Q14行可配对、无互斥冲突；小样本探索
A32: 交换尝试记录痛点 | B32: 对方对我提供的商品信息有疑虑 | C32: =COUNTIFS(数据清洗!$E$2:$E$177,1,数据清洗!$BG$2:$BG$177,1,数据清洗!$X$2:$X$177,"交换尝试记录",数据清洗!$BK$2:$BK$177,1) -> 6 | D32: =COUNTIFS(数据清洗!$E$2:$E$177,1,数据清洗!$BG$2:$BG$177,1,数据清洗!$X$2:$X$177,"交换尝试记录") -> 18 | E32: =IF(D32=0,"",C32/D32) -> 0.33333333 | F32: 仅Q12与Q14行可配对、无互斥冲突；小样本探索
A33: 交换尝试记录痛点 | B33: 没有遇到明显问题 | C33: =COUNTIFS(数据清洗!$E$2:$E$177,1,数据清洗!$BG$2:$BG$177,1,数据清洗!$X$2:$X$177,"交换尝试记录",数据清洗!$BL$2:$BL$177,1) -> 0 | D33: =COUNTIFS(数据清洗!$E$2:$E$177,1,数据清洗!$BG$2:$BG$177,1,数据清洗!$X$2:$X$177,"交换尝试记录") -> 18 | E33: =IF(D33=0,"",C33/D33) -> 0 | F33: 仅Q12与Q14行可配对、无互斥冲突；小样本探索
A34: 交换尝试记录痛点 | B34: 记不清 | C34: =COUNTIFS(数据清洗!$E$2:$E$177,1,数据清洗!$BG$2:$BG$177,1,数据清洗!$X$2:$X$177,"交换尝试记录",数据清洗!$BM$2:$BM$177,1) -> 0 | D34: =COUNTIFS(数据清洗!$E$2:$E$177,1,数据清洗!$BG$2:$BG$177,1,数据清洗!$X$2:$X$177,"交换尝试记录") -> 18 | E34: =IF(D34=0,"",C34/D34) -> 0 | F34: 仅Q12与Q14行可配对、无互斥冲突；小样本探索
A35: 交换尝试记录痛点 | B35: 遇到物流损坏或丢失 | C35: =COUNTIFS(数据清洗!$E$2:$E$177,1,数据清洗!$BG$2:$BG$177,1,数据清洗!$X$2:$X$177,"交换尝试记录",数据清洗!$BN$2:$BN$177,1) -> 2 | D35: =COUNTIFS(数据清洗!$E$2:$E$177,1,数据清洗!$BG$2:$BG$177,1,数据清洗!$X$2:$X$177,"交换尝试记录") -> 18 | E35: =IF(D35=0,"",C35/D35) -> 0.11111111 | F35: 仅Q12与Q14行可配对、无互斥冲突；小样本探索
A36: 交换尝试记录痛点 | B36: 遇到纠纷后难以解决 | C36: =COUNTIFS(数据清洗!$E$2:$E$177,1,数据清洗!$BG$2:$BG$177,1,数据清洗!$X$2:$X$177,"交换尝试记录",数据清洗!$BO$2:$BO$177,1) -> 6 | D36: =COUNTIFS(数据清洗!$E$2:$E$177,1,数据清洗!$BG$2:$BG$177,1,数据清洗!$X$2:$X$177,"交换尝试记录") -> 18 | E36: =IF(D36=0,"",C36/D36) -> 0.33333333 | F36: 仅Q12与Q14行可配对、无互斥冲突；小样本探索
A37: 交换尝试记录痛点 | B37: 难以判断对方提供的商品信息是否真实【仅交换行】 | C37: =COUNTIFS(数据清洗!$E$2:$E$177,1,数据清洗!$BG$2:$BG$177,1,数据清洗!$X$2:$X$177,"交换尝试记录",数据清洗!$BP$2:$BP$177,1) -> 9 | D37: =COUNTIFS(数据清洗!$E$2:$E$177,1,数据清洗!$BG$2:$BG$177,1,数据清洗!$X$2:$X$177,"交换尝试记录") -> 18 | E37: =IF(D37=0,"",C37/D37) -> 0.5 | F37: 仅Q12与Q14行可配对、无互斥冲突；小样本探索
A38: 交换尝试记录痛点 | B38: 难以就价格／补差价达成一致 | C38: =COUNTIFS(数据清洗!$E$2:$E$177,1,数据清洗!$BG$2:$BG$177,1,数据清洗!$X$2:$X$177,"交换尝试记录",数据清洗!$BQ$2:$BQ$177,1) -> 5 | D38: =COUNTIFS(数据清洗!$E$2:$E$177,1,数据清洗!$BG$2:$BG$177,1,数据清洗!$X$2:$X$177,"交换尝试记录") -> 18 | E38: =IF(D38=0,"",C38/D38) -> 0.27777778 | F38: 仅Q12与Q14行可配对、无互斥冲突；小样本探索
A39: 交换尝试记录痛点 | B39: 难以找到想要我这件周边的人 | C39: =COUNTIFS(数据清洗!$E$2:$E$177,1,数据清洗!$BG$2:$BG$177,1,数据清洗!$X$2:$X$177,"交换尝试记录",数据清洗!$BR$2:$BR$177,1) -> 3 | D39: =COUNTIFS(数据清洗!$E$2:$E$177,1,数据清洗!$BG$2:$BG$177,1,数据清洗!$X$2:$X$177,"交换尝试记录") -> 18 | E39: =IF(D39=0,"",C39/D39) -> 0.16666667 | F39: 仅Q12与Q14行可配对、无互斥冲突；小样本探索
A40: 交换尝试记录痛点 | B40: 难以找到愿意拿出我想要款式的交换对象【仅交换行】 | C40: =COUNTIFS(数据清洗!$E$2:$E$177,1,数据清洗!$BG$2:$BG$177,1,数据清洗!$X$2:$X$177,"交换尝试记录",数据清洗!$BS$2:$BS$177,1) -> 9 | D40: =COUNTIFS(数据清洗!$E$2:$E$177,1,数据清洗!$BG$2:$BG$177,1,数据清洗!$X$2:$X$177,"交换尝试记录") -> 18 | E40: =IF(D40=0,"",C40/D40) -> 0.5 | F40: 仅Q12与Q14行可配对、无互斥冲突；小样本探索
A41: 交换尝试记录痛点 | B41: 需要反复沟通品相、包装等细节 | C41: =COUNTIFS(数据清洗!$E$2:$E$177,1,数据清洗!$BG$2:$BG$177,1,数据清洗!$X$2:$X$177,"交换尝试记录",数据清洗!$BT$2:$BT$177,1) -> 9 | D41: =COUNTIFS(数据清洗!$E$2:$E$177,1,数据清洗!$BG$2:$BG$177,1,数据清洗!$X$2:$X$177,"交换尝试记录") -> 18 | E41: =IF(D41=0,"",C41/D41) -> 0.5 | F41: 仅Q12与Q14行可配对、无互斥冲突；小样本探索

Sheet 功能意向
A1: 功能意向
A2: Q6缺少服务与状态配对，不能估计市集认知/使用率。Q16只统计明确可能性填写；名称被勾选不等于愿意使用。
A5: 功能 | B5: 高意向 n | C5: 有效 N | D5: 高意向 n/N | E5: 缺失或歧义 | F5: 不适用人数 | G5: 排除不适用后
A6: 发布出售 | B6: =COUNTIFS(数据清洗!$E$2:$E$177,1,数据清洗!$CQ$2:$CQ$177,4)+COUNTIFS(数据清洗!$E$2:$E$177,1,数据清洗!$CQ$2:$CQ$177,5) -> 47 | C6: =COUNTIFS(数据清洗!$E$2:$E$177,1,数据清洗!$CQ$2:$CQ$177,"<>") -> 59 | D6: =IF(C6=0,"",B6/C6) -> 0.79661017 | E6: =COUNTIFS(数据清洗!$E$2:$E$177,1)-C6 -> 63 | F6: =COUNTIFS(数据清洗!$E$2:$E$177,1,数据清洗!$CQ$2:$CQ$177,97) -> 1 | G6: =IF(C6-F6=0,"",B6/(C6-F6)) -> 0.81034483
A7: 寻找交换 | B7: =COUNTIFS(数据清洗!$E$2:$E$177,1,数据清洗!$CS$2:$CS$177,4)+COUNTIFS(数据清洗!$E$2:$E$177,1,数据清洗!$CS$2:$CS$177,5) -> 41 | C7: =COUNTIFS(数据清洗!$E$2:$E$177,1,数据清洗!$CS$2:$CS$177,"<>") -> 63 | D7: =IF(C7=0,"",B7/C7) -> 0.65079365 | E7: =COUNTIFS(数据清洗!$E$2:$E$177,1)-C7 -> 59 | F7: =COUNTIFS(数据清洗!$E$2:$E$177,1,数据清洗!$CS$2:$CS$177,97) -> 0 | G7: =IF(C7-F7=0,"",B7/(C7-F7)) -> 0.65079365
A8: IP兴趣标签 | B8: =COUNTIFS(数据清洗!$E$2:$E$177,1,数据清洗!$CU$2:$CU$177,4)+COUNTIFS(数据清洗!$E$2:$E$177,1,数据清洗!$CU$2:$CU$177,5) -> 44 | C8: =COUNTIFS(数据清洗!$E$2:$E$177,1,数据清洗!$CU$2:$CU$177,"<>") -> 57 | D8: =IF(C8=0,"",B8/C8) -> 0.77192982 | E8: =COUNTIFS(数据清洗!$E$2:$E$177,1)-C8 -> 65 | F8: =COUNTIFS(数据清洗!$E$2:$E$177,1,数据清洗!$CU$2:$CU$177,97) -> 3 | G8: =IF(C8-F8=0,"",B8/(C8-F8)) -> 0.81481481
A9: 订单来源信息 | B9: =COUNTIFS(数据清洗!$E$2:$E$177,1,数据清洗!$CW$2:$CW$177,4)+COUNTIFS(数据清洗!$E$2:$E$177,1,数据清洗!$CW$2:$CW$177,5) -> 28 | C9: =COUNTIFS(数据清洗!$E$2:$E$177,1,数据清洗!$CW$2:$CW$177,"<>") -> 52 | D9: =IF(C9=0,"",B9/C9) -> 0.53846154 | E9: =COUNTIFS(数据清洗!$E$2:$E$177,1)-C9 -> 70 | F9: =COUNTIFS(数据清洗!$E$2:$E$177,1,数据清洗!$CW$2:$CW$177,97) -> 2 | G9: =IF(C9-F9=0,"",B9/(C9-F9)) -> 0.56
A11: 高意向=比较可能或非常可能。四项分母52–63不等；非随机缺失明显，不可按百分比直接排功能优先级。
A13: 题目/范围 | B13: 选项 | C13: 人数 n | D13: 有效分母 N | E13: 比例 n/N | F13: 口径
A14: Q17 顾虑（多选） | B14: 不确定付款、发货和纠纷处理是否有保障 | C14: =COUNTIFS(数据清洗!$E$2:$E$177,1,数据清洗!$BU$2:$BU$177,1,数据清洗!$BV$2:$BV$177,1) -> 51 | D14: =COUNTIFS(数据清洗!$E$2:$E$177,1,数据清洗!$BU$2:$BU$177,1) -> 117 | E14: =IF(D14=0,"",C14/D14) -> 0.43589744 | F14: Q17顾虑；排除互斥项混选
A15: Q17 顾虑（多选） | B15: 不确定商品信息是否可信 | C15: =COUNTIFS(数据清洗!$E$2:$E$177,1,数据清洗!$BU$2:$BU$177,1,数据清洗!$BW$2:$BW$177,1) -> 42 | D15: =COUNTIFS(数据清洗!$E$2:$E$177,1,数据清洗!$BU$2:$BU$177,1) -> 117 | E15: =IF(D15=0,"",C15/D15) -> 0.35897436 | F15: Q17顾虑；排除互斥项混选
A16: Q17 顾虑（多选） | B16: 不确定能否找到合适的交易对象 | C16: =COUNTIFS(数据清洗!$E$2:$E$177,1,数据清洗!$BU$2:$BU$177,1,数据清洗!$BX$2:$BX$177,1) -> 45 | D16: =COUNTIFS(数据清洗!$E$2:$E$177,1,数据清洗!$BU$2:$BU$177,1) -> 117 | E16: =IF(D16=0,"",C16/D16) -> 0.38461538 | F16: Q17顾虑；排除互斥项混选
A17: Q17 顾虑（多选） | B17: 信息不足，暂时无法判断 | C17: =COUNTIFS(数据清洗!$E$2:$E$177,1,数据清洗!$BU$2:$BU$177,1,数据清洗!$BY$2:$BY$177,1) -> 1 | D17: =COUNTIFS(数据清洗!$E$2:$E$177,1,数据清洗!$BU$2:$BU$177,1) -> 117 | E17: =IF(D17=0,"",C17/D17) -> 0.0085470085 | F17: Q17顾虑；排除互斥项混选
A18: Q17 顾虑（多选） | B18: 其他，请注明: | C18: =COUNTIFS(数据清洗!$E$2:$E$177,1,数据清洗!$BU$2:$BU$177,1,数据清洗!$BZ$2:$BZ$177,1) -> 6 | D18: =COUNTIFS(数据清洗!$E$2:$E$177,1,数据清洗!$BU$2:$BU$177,1) -> 117 | E18: =IF(D18=0,"",C18/D18) -> 0.051282051 | F18: Q17顾虑；排除互斥项混选
A19: Q17 顾虑（多选） | B19: 担心可交易的商品范围有限 | C19: =COUNTIFS(数据清洗!$E$2:$E$177,1,数据清洗!$BU$2:$BU$177,1,数据清洗!$CA$2:$CA$177,1) -> 17 | D19: =COUNTIFS(数据清洗!$E$2:$E$177,1,数据清洗!$BU$2:$BU$177,1) -> 117 | E19: =IF(D19=0,"",C19/D19) -> 0.14529915 | F19: Q17顾虑；排除互斥项混选
A20: Q17 顾虑（多选） | B20: 担心手续费或其他使用成本 | C20: =COUNTIFS(数据清洗!$E$2:$E$177,1,数据清洗!$BU$2:$BU$177,1,数据清洗!$CB$2:$CB$177,1) -> 25 | D20: =COUNTIFS(数据清洗!$E$2:$E$177,1,数据清洗!$BU$2:$BU$177,1) -> 117 | E20: =IF(D20=0,"",C20/D20) -> 0.21367521 | F20: Q17顾虑；排除互斥项混选
A21: Q17 顾虑（多选） | B21: 担心操作或沟通过于麻烦 | C21: =COUNTIFS(数据清洗!$E$2:$E$177,1,数据清洗!$BU$2:$BU$177,1,数据清洗!$CC$2:$CC$177,1) -> 26 | D21: =COUNTIFS(数据清洗!$E$2:$E$177,1,数据清洗!$BU$2:$BU$177,1) -> 117 | E21: =IF(D21=0,"",C21/D21) -> 0.22222222 | F21: Q17顾虑；排除互斥项混选
A22: Q17 顾虑（多选） | B22: 担心暴露兴趣、购买记录等隐私 | C22: =COUNTIFS(数据清洗!$E$2:$E$177,1,数据清洗!$BU$2:$BU$177,1,数据清洗!$CD$2:$CD$177,1) -> 36 | D22: =COUNTIFS(数据清洗!$E$2:$E$177,1,数据清洗!$BU$2:$BU$177,1) -> 117 | E22: =IF(D22=0,"",C22/D22) -> 0.30769231 | F22: Q17顾虑；排除互斥项混选
A23: Q17 顾虑（多选） | B23: 暂无顾虑 | C23: =COUNTIFS(数据清洗!$E$2:$E$177,1,数据清洗!$BU$2:$BU$177,1,数据清洗!$CE$2:$CE$177,1) -> 3 | D23: =COUNTIFS(数据清洗!$E$2:$E$177,1,数据清洗!$BU$2:$BU$177,1) -> 117 | E23: =IF(D23=0,"",C23/D23) -> 0.025641026 | F23: Q17顾虑；排除互斥项混选
A24: Q18 主要原因（单一回答） | B24: 其他，请注明: | C24: =COUNTIFS(数据清洗!$E$2:$E$177,1,数据清洗!$CF$2:$CF$177,1,数据清洗!$CG$2:$CG$177,1) -> 2 | D24: =COUNTIFS(数据清洗!$E$2:$E$177,1,数据清洗!$CF$2:$CF$177,1) -> 49 | E24: =IF(D24=0,"",C24/D24) -> 0.040816327 | F24: Q18仅保留单一选择，不能把多选解释为最主要原因
A25: Q18 主要原因（单一回答） | B25: 希望尝试更多渠道，增加找到对象的机会 | C25: =COUNTIFS(数据清洗!$E$2:$E$177,1,数据清洗!$CF$2:$CF$177,1,数据清洗!$CH$2:$CH$177,1) -> 7 | D25: =COUNTIFS(数据清洗!$E$2:$E$177,1,数据清洗!$CF$2:$CF$177,1) -> 49 | E25: =IF(D25=0,"",C25/D25) -> 0.14285714 | F25: Q18仅保留单一选择，不能把多选解释为最主要原因
A26: Q18 主要原因（单一回答） | B26: 希望更容易遇到相同IP的同好 | C26: =COUNTIFS(数据清洗!$E$2:$E$177,1,数据清洗!$CF$2:$CF$177,1,数据清洗!$CI$2:$CI$177,1) -> 5 | D26: =COUNTIFS(数据清洗!$E$2:$E$177,1,数据清洗!$CF$2:$CF$177,1) -> 49 | E26: =IF(D26=0,"",C26/D26) -> 0.10204082 | F26: Q18仅保留单一选择，不能把多选解释为最主要原因
A27: Q18 主要原因（单一回答） | B27: 希望有更多可参考的商品来源信息 | C27: =COUNTIFS(数据清洗!$E$2:$E$177,1,数据清洗!$CF$2:$CF$177,1,数据清洗!$CJ$2:$CJ$177,1) -> 6 | D27: =COUNTIFS(数据清洗!$E$2:$E$177,1,数据清洗!$CF$2:$CF$177,1) -> 49 | E27: =IF(D27=0,"",C27/D27) -> 0.12244898 | F27: Q18仅保留单一选择，不能把多选解释为最主要原因
A28: Q18 主要原因（单一回答） | B28: 我是否使用主要取决于交易保障规则 | C28: =COUNTIFS(数据清洗!$E$2:$E$177,1,数据清洗!$CF$2:$CF$177,1,数据清洗!$CK$2:$CK$177,1) -> 3 | D28: =COUNTIFS(数据清洗!$E$2:$E$177,1,数据清洗!$CF$2:$CF$177,1) -> 49 | E28: =IF(D28=0,"",C28/D28) -> 0.06122449 | F28: Q18仅保留单一选择，不能把多选解释为最主要原因
A29: Q18 主要原因（单一回答） | B29: 我是否使用主要取决于费用 | C29: =COUNTIFS(数据清洗!$E$2:$E$177,1,数据清洗!$CF$2:$CF$177,1,数据清洗!$CL$2:$CL$177,1) -> 2 | D29: =COUNTIFS(数据清洗!$E$2:$E$177,1,数据清洗!$CF$2:$CF$177,1) -> 49 | E29: =IF(D29=0,"",C29/D29) -> 0.040816327 | F29: Q18仅保留单一选择，不能把多选解释为最主要原因
A30: Q18 主要原因（单一回答） | B30: 我是否使用主要取决于隐私保护方式 | C30: =COUNTIFS(数据清洗!$E$2:$E$177,1,数据清洗!$CF$2:$CF$177,1,数据清洗!$CM$2:$CM$177,1) -> 3 | D30: =COUNTIFS(数据清洗!$E$2:$E$177,1,数据清洗!$CF$2:$CF$177,1) -> 49 | E30: =IF(D30=0,"",C30/D30) -> 0.06122449 | F30: Q18仅保留单一选择，不能把多选解释为最主要原因
A31: Q18 主要原因（单一回答） | B31: 现有渠道已经能满足我的需要 | C31: =COUNTIFS(数据清洗!$E$2:$E$177,1,数据清洗!$CF$2:$CF$177,1,数据清洗!$CN$2:$CN$177,1) -> 7 | D31: =COUNTIFS(数据清洗!$E$2:$E$177,1,数据清洗!$CF$2:$CF$177,1) -> 49 | E31: =IF(D31=0,"",C31/D31) -> 0.14285714 | F31: Q18仅保留单一选择，不能把多选解释为最主要原因
A32: Q18 主要原因（单一回答） | B32: 目前没有出售或交换需求 | C32: =COUNTIFS(数据清洗!$E$2:$E$177,1,数据清洗!$CF$2:$CF$177,1,数据清洗!$CO$2:$CO$177,1) -> 14 | D32: =COUNTIFS(数据清洗!$E$2:$E$177,1,数据清洗!$CF$2:$CF$177,1) -> 49 | E32: =IF(D32=0,"",C32/D32) -> 0.28571429 | F32: Q18仅保留单一选择，不能把多选解释为最主要原因
A33: Q18 主要原因（单一回答） | B33: 需要更多信息才能判断 | C33: =COUNTIFS(数据清洗!$E$2:$E$177,1,数据清洗!$CF$2:$CF$177,1,数据清洗!$CP$2:$CP$177,1) -> 0 | D33: =COUNTIFS(数据清洗!$E$2:$E$177,1,数据清洗!$CF$2:$CF$177,1) -> 49 | E33: =IF(D33=0,"",C33/D33) -> 0 | F33: Q18仅保留单一选择，不能把多选解释为最主要原因
A34: Q16 发布出售 | B34: 非常不可能 | C34: =COUNTIFS(数据清洗!$E$2:$E$177,1,数据清洗!$CQ$2:$CQ$177,"<>",数据清洗!$CQ$2:$CQ$177,1) -> 0 | D34: =COUNTIFS(数据清洗!$E$2:$E$177,1,数据清洗!$CQ$2:$CQ$177,"<>") -> 59 | E34: =IF(D34=0,"",C34/D34) -> 0 | F34: 发布周边出售信息；仅有效填写者，含不适用
A35: Q16 发布出售 | B35: 比较不可能 | C35: =COUNTIFS(数据清洗!$E$2:$E$177,1,数据清洗!$CQ$2:$CQ$177,"<>",数据清洗!$CQ$2:$CQ$177,2) -> 2 | D35: =COUNTIFS(数据清洗!$E$2:$E$177,1,数据清洗!$CQ$2:$CQ$177,"<>") -> 59 | E35: =IF(D35=0,"",C35/D35) -> 0.033898305 | F35: 发布周边出售信息；仅有效填写者，含不适用
A36: Q16 发布出售 | B36: 不确定或需更多规则 | C36: =COUNTIFS(数据清洗!$E$2:$E$177,1,数据清洗!$CQ$2:$CQ$177,"<>",数据清洗!$CQ$2:$CQ$177,3) -> 9 | D36: =COUNTIFS(数据清洗!$E$2:$E$177,1,数据清洗!$CQ$2:$CQ$177,"<>") -> 59 | E36: =IF(D36=0,"",C36/D36) -> 0.15254237 | F36: 发布周边出售信息；仅有效填写者，含不适用
A37: Q16 发布出售 | B37: 比较可能 | C37: =COUNTIFS(数据清洗!$E$2:$E$177,1,数据清洗!$CQ$2:$CQ$177,"<>",数据清洗!$CQ$2:$CQ$177,4) -> 25 | D37: =COUNTIFS(数据清洗!$E$2:$E$177,1,数据清洗!$CQ$2:$CQ$177,"<>") -> 59 | E37: =IF(D37=0,"",C37/D37) -> 0.42372881 | F37: 发布周边出售信息；仅有效填写者，含不适用
A38: Q16 发布出售 | B38: 非常可能 | C38: =COUNTIFS(数据清洗!$E$2:$E$177,1,数据清洗!$CQ$2:$CQ$177,"<>",数据清洗!$CQ$2:$CQ$177,5) -> 22 | D38: =COUNTIFS(数据清洗!$E$2:$E$177,1,数据清洗!$CQ$2:$CQ$177,"<>") -> 59 | E38: =IF(D38=0,"",C38/D38) -> 0.37288136 | F38: 发布周边出售信息；仅有效填写者，含不适用
A39: Q16 发布出售 | B39: 不适用 | C39: =COUNTIFS(数据清洗!$E$2:$E$177,1,数据清洗!$CQ$2:$CQ$177,"<>",数据清洗!$CQ$2:$CQ$177,97) -> 1 | D39: =COUNTIFS(数据清洗!$E$2:$E$177,1,数据清洗!$CQ$2:$CQ$177,"<>") -> 59 | E39: =IF(D39=0,"",C39/D39) -> 0.016949153 | F39: 发布周边出售信息；仅有效填写者，含不适用
A40: Q16 寻找交换 | B40: 非常不可能 | C40: =COUNTIFS(数据清洗!$E$2:$E$177,1,数据清洗!$CS$2:$CS$177,"<>",数据清洗!$CS$2:$CS$177,1) -> 3 | D40: =COUNTIFS(数据清洗!$E$2:$E$177,1,数据清洗!$CS$2:$CS$177,"<>") -> 63 | E40: =IF(D40=0,"",C40/D40) -> 0.047619048 | F40: 寻找周边交换对象；仅有效填写者，含不适用
A41: Q16 寻找交换 | B41: 比较不可能 | C41: =COUNTIFS(数据清洗!$E$2:$E$177,1,数据清洗!$CS$2:$CS$177,"<>",数据清洗!$CS$2:$CS$177,2) -> 5 | D41: =COUNTIFS(数据清洗!$E$2:$E$177,1,数据清洗!$CS$2:$CS$177,"<>") -> 63 | E41: =IF(D41=0,"",C41/D41) -> 0.079365079 | F41: 寻找周边交换对象；仅有效填写者，含不适用
A42: Q16 寻找交换 | B42: 不确定或需更多规则 | C42: =COUNTIFS(数据清洗!$E$2:$E$177,1,数据清洗!$CS$2:$CS$177,"<>",数据清洗!$CS$2:$CS$177,3) -> 14 | D42: =COUNTIFS(数据清洗!$E$2:$E$177,1,数据清洗!$CS$2:$CS$177,"<>") -> 63 | E42: =IF(D42=0,"",C42/D42) -> 0.22222222 | F42: 寻找周边交换对象；仅有效填写者，含不适用
A43: Q16 寻找交换 | B43: 比较可能 | C43: =COUNTIFS(数据清洗!$E$2:$E$177,1,数据清洗!$CS$2:$CS$177,"<>",数据清洗!$CS$2:$CS$177,4) -> 22 | D43: =COUNTIFS(数据清洗!$E$2:$E$177,1,数据清洗!$CS$2:$CS$177,"<>") -> 63 | E43: =IF(D43=0,"",C43/D43) -> 0.34920635 | F43: 寻找周边交换对象；仅有效填写者，含不适用
A44: Q16 寻找交换 | B44: 非常可能 | C44: =COUNTIFS(数据清洗!$E$2:$E$177,1,数据清洗!$CS$2:$CS$177,"<>",数据清洗!$CS$2:$CS$177,5) -> 19 | D44: =COUNTIFS(数据清洗!$E$2:$E$177,1,数据清洗!$CS$2:$CS$177,"<>") -> 63 | E44: =IF(D44=0,"",C44/D44) -> 0.3015873 | F44: 寻找周边交换对象；仅有效填写者，含不适用
...

Sheet 用户分群
A1: 用户分群
A2: 出售与交换为导出可确认的行为记录，不能解释为仅出售/仅交换用户。分母少于5不显示比例，少于30只作探索。
A5: 分组维度 | B5: 组别 | C5: 组人数 | D5: 有闲置 n | E5: 闲置 n/N | F5: 出售高意向 n | G5: 出售有效 N | H5: 出售意向 n/N | I5: 交换高意向 n | J5: 交换有效 N | K5: 交换意向 n/N
A6: 近12月购买 | B6: 买过 | C6: =COUNTIFS(数据清洗!$E$2:$E$177,1,数据清洗!$L$2:$L$177,1) -> 94 | D6: =COUNTIFS(数据清洗!$E$2:$E$177,1,数据清洗!$L$2:$L$177,1,数据清洗!$M$2:$M$177,"有") -> 46 | E6: =IF(C6<5,"",D6/C6) -> 0.4893617 | F6: =COUNTIFS(数据清洗!$E$2:$E$177,1,数据清洗!$L$2:$L$177,1,数据清洗!$CQ$2:$CQ$177,4)+COUNTIFS(数据清洗!$E$2:$E$177,1,数据清洗!$L$2:$L$177,1,数据清洗!$CQ$2:$CQ$177,5) -> 47 | G6: =COUNTIFS(数据清洗!$E$2:$E$177,1,数据清洗!$L$2:$L$177,1,数据清洗!$CQ$2:$CQ$177,"<>") -> 58 | H6: =IF(G6<5,"",F6/G6) -> 0.81034483 | I6: =COUNTIFS(数据清洗!$E$2:$E$177,1,数据清洗!$L$2:$L$177,1,数据清洗!$CS$2:$CS$177,4)+COUNTIFS(数据清洗!$E$2:$E$177,1,数据清洗!$L$2:$L$177,1,数据清洗!$CS$2:$CS$177,5) -> 40 | J6: =COUNTIFS(数据清洗!$E$2:$E$177,1,数据清洗!$L$2:$L$177,1,数据清洗!$CS$2:$CS$177,"<>") -> 62 | K6: =IF(J6<5,"",I6/J6) -> 0.64516129
A7: 近12月购买 | B7: 未购买 | C7: =COUNTIFS(数据清洗!$E$2:$E$177,1,数据清洗!$L$2:$L$177,0) -> 28 | D7: =COUNTIFS(数据清洗!$E$2:$E$177,1,数据清洗!$L$2:$L$177,0,数据清洗!$M$2:$M$177,"有") -> 12 | E7: =IF(C7<5,"",D7/C7) -> 0.42857143 | F7: =COUNTIFS(数据清洗!$E$2:$E$177,1,数据清洗!$L$2:$L$177,0,数据清洗!$CQ$2:$CQ$177,4)+COUNTIFS(数据清洗!$E$2:$E$177,1,数据清洗!$L$2:$L$177,0,数据清洗!$CQ$2:$CQ$177,5) -> 0 | G7: =COUNTIFS(数据清洗!$E$2:$E$177,1,数据清洗!$L$2:$L$177,0,数据清洗!$CQ$2:$CQ$177,"<>") -> 1 | H7: =IF(G7<5,"",F7/G7) | I7: =COUNTIFS(数据清洗!$E$2:$E$177,1,数据清洗!$L$2:$L$177,0,数据清洗!$CS$2:$CS$177,4)+COUNTIFS(数据清洗!$E$2:$E$177,1,数据清洗!$L$2:$L$177,0,数据清洗!$CS$2:$CS$177,5) -> 1 | J7: =COUNTIFS(数据清洗!$E$2:$E$177,1,数据清洗!$L$2:$L$177,0,数据清洗!$CS$2:$CS$177,"<>") -> 1 | K7: =IF(J7<5,"",I7/J7)
A8: 闲置经历 | B8: 有 | C8: =COUNTIFS(数据清洗!$E$2:$E$177,1,数据清洗!$M$2:$M$177,"有") -> 58 | D8: =COUNTIFS(数据清洗!$E$2:$E$177,1,数据清洗!$M$2:$M$177,"有",数据清洗!$M$2:$M$177,"有") -> 58 | E8: =IF(C8<5,"",D8/C8) -> 1 | F8: =COUNTIFS(数据清洗!$E$2:$E$177,1,数据清洗!$M$2:$M$177,"有",数据清洗!$CQ$2:$CQ$177,4)+COUNTIFS(数据清洗!$E$2:$E$177,1,数据清洗!$M$2:$M$177,"有",数据清洗!$CQ$2:$CQ$177,5) -> 27 | G8: =COUNTIFS(数据清洗!$E$2:$E$177,1,数据清洗!$M$2:$M$177,"有",数据清洗!$CQ$2:$CQ$177,"<>") -> 33 | H8: =IF(G8<5,"",F8/G8) -> 0.81818182 | I8: =COUNTIFS(数据清洗!$E$2:$E$177,1,数据清洗!$M$2:$M$177,"有",数据清洗!$CS$2:$CS$177,4)+COUNTIFS(数据清洗!$E$2:$E$177,1,数据清洗!$M$2:$M$177,"有",数据清洗!$CS$2:$CS$177,5) -> 22 | J8: =COUNTIFS(数据清洗!$E$2:$E$177,1,数据清洗!$M$2:$M$177,"有",数据清洗!$CS$2:$CS$177,"<>") -> 33 | K8: =IF(J8<5,"",I8/J8) -> 0.66666667
A9: 闲置经历 | B9: 没有 | C9: =COUNTIFS(数据清洗!$E$2:$E$177,1,数据清洗!$M$2:$M$177,"没有") -> 43 | D9: =COUNTIFS(数据清洗!$E$2:$E$177,1,数据清洗!$M$2:$M$177,"没有",数据清洗!$M$2:$M$177,"有") -> 0 | E9: =IF(C9<5,"",D9/C9) -> 0 | F9: =COUNTIFS(数据清洗!$E$2:$E$177,1,数据清洗!$M$2:$M$177,"没有",数据清洗!$CQ$2:$CQ$177,4)+COUNTIFS(数据清洗!$E$2:$E$177,1,数据清洗!$M$2:$M$177,"没有",数据清洗!$CQ$2:$CQ$177,5) -> 18 | G9: =COUNTIFS(数据清洗!$E$2:$E$177,1,数据清洗!$M$2:$M$177,"没有",数据清洗!$CQ$2:$CQ$177,"<>") -> 22 | H9: =IF(G9<5,"",F9/G9) -> 0.81818182 | I9: =COUNTIFS(数据清洗!$E$2:$E$177,1,数据清洗!$M$2:$M$177,"没有",数据清洗!$CS$2:$CS$177,4)+COUNTIFS(数据清洗!$E$2:$E$177,1,数据清洗!$M$2:$M$177,"没有",数据清洗!$CS$2:$CS$177,5) -> 16 | J9: =COUNTIFS(数据清洗!$E$2:$E$177,1,数据清洗!$M$2:$M$177,"没有",数据清洗!$CS$2:$CS$177,"<>") -> 25 | K9: =IF(J9<5,"",I9/J9) -> 0.64
A10: 闲置经历 | B10: 不确定 | C10: =COUNTIFS(数据清洗!$E$2:$E$177,1,数据清洗!$M$2:$M$177,"不确定") -> 21 | D10: =COUNTIFS(数据清洗!$E$2:$E$177,1,数据清洗!$M$2:$M$177,"不确定",数据清洗!$M$2:$M$177,"有") -> 0 | E10: =IF(C10<5,"",D10/C10) -> 0 | F10: =COUNTIFS(数据清洗!$E$2:$E$177,1,数据清洗!$M$2:$M$177,"不确定",数据清洗!$CQ$2:$CQ$177,4)+COUNTIFS(数据清洗!$E$2:$E$177,1,数据清洗!$M$2:$M$177,"不确定",数据清洗!$CQ$2:$CQ$177,5) -> 2 | G10: =COUNTIFS(数据清洗!$E$2:$E$177,1,数据清洗!$M$2:$M$177,"不确定",数据清洗!$CQ$2:$CQ$177,"<>") -> 4 | H10: =IF(G10<5,"",F10/G10) | I10: =COUNTIFS(数据清洗!$E$2:$E$177,1,数据清洗!$M$2:$M$177,"不确定",数据清洗!$CS$2:$CS$177,4)+COUNTIFS(数据清洗!$E$2:$E$177,1,数据清洗!$M$2:$M$177,"不确定",数据清洗!$CS$2:$CS$177,5) -> 3 | J10: =COUNTIFS(数据清洗!$E$2:$E$177,1,数据清洗!$M$2:$M$177,"不确定",数据清洗!$CS$2:$CS$177,"<>") -> 5 | K10: =IF(J10<5,"",I10/J10) -> 0.6
A11: B站频率 | B11: 几乎每天 | C11: =COUNTIFS(数据清洗!$E$2:$E$177,1,数据清洗!$J$2:$J$177,"几乎每天") -> 39 | D11: =COUNTIFS(数据清洗!$E$2:$E$177,1,数据清洗!$J$2:$J$177,"几乎每天",数据清洗!$M$2:$M$177,"有") -> 17 | E11: =IF(C11<5,"",D11/C11) -> 0.43589744 | F11: =COUNTIFS(数据清洗!$E$2:$E$177,1,数据清洗!$J$2:$J$177,"几乎每天",数据清洗!$CQ$2:$CQ$177,4)+COUNTIFS(数据清洗!$E$2:$E$177,1,数据清洗!$J$2:$J$177,"几乎每天",数据清洗!$CQ$2:$CQ$177,5) -> 13 | G11: =COUNTIFS(数据清洗!$E$2:$E$177,1,数据清洗!$J$2:$J$177,"几乎每天",数据清洗!$CQ$2:$CQ$177,"<>") -> 17 | H11: =IF(G11<5,"",F11/G11) -> 0.76470588 | I11: =COUNTIFS(数据清洗!$E$2:$E$177,1,数据清洗!$J$2:$J$177,"几乎每天",数据清洗!$CS$2:$CS$177,4)+COUNTIFS(数据清洗!$E$2:$E$177,1,数据清洗!$J$2:$J$177,"几乎每天",数据清洗!$CS$2:$CS$177,5) -> 11 | J11: =COUNTIFS(数据清洗!$E$2:$E$177,1,数据清洗!$J$2:$J$177,"几乎每天",数据清洗!$CS$2:$CS$177,"<>") -> 18 | K11: =IF(J11<5,"",I11/J11) -> 0.61111111
A12: B站频率 | B12: 每周3–6天 | C12: =COUNTIFS(数据清洗!$E$2:$E$177,1,数据清洗!$J$2:$J$177,"每周3–6天") -> 34 | D12: =COUNTIFS(数据清洗!$E$2:$E$177,1,数据清洗!$J$2:$J$177,"每周3–6天",数据清洗!$M$2:$M$177,"有") -> 17 | E12: =IF(C12<5,"",D12/C12) -> 0.5 | F12: =COUNTIFS(数据清洗!$E$2:$E$177,1,数据清洗!$J$2:$J$177,"每周3–6天",数据清洗!$CQ$2:$CQ$177,4)+COUNTIFS(数据清洗!$E$2:$E$177,1,数据清洗!$J$2:$J$177,"每周3–6天",数据清洗!$CQ$2:$CQ$177,5) -> 11 | G12: =COUNTIFS(数据清洗!$E$2:$E$177,1,数据清洗!$J$2:$J$177,"每周3–6天",数据清洗!$CQ$2:$CQ$177,"<>") -> 14 | H12: =IF(G12<5,"",F12/G12) -> 0.78571429 | I12: =COUNTIFS(数据清洗!$E$2:$E$177,1,数据清洗!$J$2:$J$177,"每周3–6天",数据清洗!$CS$2:$CS$177,4)+COUNTIFS(数据清洗!$E$2:$E$177,1,数据清洗!$J$2:$J$177,"每周3–6天",数据清洗!$CS$2:$CS$177,5) -> 9 | J12: =COUNTIFS(数据清洗!$E$2:$E$177,1,数据清洗!$J$2:$J$177,"每周3–6天",数据清洗!$CS$2:$CS$177,"<>") -> 14 | K12: =IF(J12<5,"",I12/J12) -> 0.64285714
A13: B站频率 | B13: 每周1–2天 | C13: =COUNTIFS(数据清洗!$E$2:$E$177,1,数据清洗!$J$2:$J$177,"每周1–2天") -> 29 | D13: =COUNTIFS(数据清洗!$E$2:$E$177,1,数据清洗!$J$2:$J$177,"每周1–2天",数据清洗!$M$2:$M$177,"有") -> 17 | E13: =IF(C13<5,"",D13/C13) -> 0.5862069 | F13: =COUNTIFS(数据清洗!$E$2:$E$177,1,数据清洗!$J$2:$J$177,"每周1–2天",数据清洗!$CQ$2:$CQ$177,4)+COUNTIFS(数据清洗!$E$2:$E$177,1,数据清洗!$J$2:$J$177,"每周1–2天",数据清洗!$CQ$2:$CQ$177,5) -> 16 | G13: =COUNTIFS(数据清洗!$E$2:$E$177,1,数据清洗!$J$2:$J$177,"每周1–2天",数据清洗!$CQ$2:$CQ$177,"<>") -> 20 | H13: =IF(G13<5,"",F13/G13) -> 0.8 | I13: =COUNTIFS(数据清洗!$E$2:$E$177,1,数据清洗!$J$2:$J$177,"每周1–2天",数据清洗!$CS$2:$CS$177,4)+COUNTIFS(数据清洗!$E$2:$E$177,1,数据清洗!$J$2:$J$177,"每周1–2天",数据清洗!$CS$2:$CS$177,5) -> 15 | J13: =COUNTIFS(数据清洗!$E$2:$E$177,1,数据清洗!$J$2:$J$177,"每周1–2天",数据清洗!$CS$2:$CS$177,"<>") -> 23 | K13: =IF(J13<5,"",I13/J13) -> 0.65217391
A14: B站频率 | B14: 少于每周1天 | C14: =COUNTIFS(数据清洗!$E$2:$E$177,1,数据清洗!$J$2:$J$177,"少于每周1天") -> 13 | D14: =COUNTIFS(数据清洗!$E$2:$E$177,1,数据清洗!$J$2:$J$177,"少于每周1天",数据清洗!$M$2:$M$177,"有") -> 5 | E14: =IF(C14<5,"",D14/C14) -> 0.38461538 | F14: =COUNTIFS(数据清洗!$E$2:$E$177,1,数据清洗!$J$2:$J$177,"少于每周1天",数据清洗!$CQ$2:$CQ$177,4)+COUNTIFS(数据清洗!$E$2:$E$177,1,数据清洗!$J$2:$J$177,"少于每周1天",数据清洗!$CQ$2:$CQ$177,5) -> 6 | G14: =COUNTIFS(数据清洗!$E$2:$E$177,1,数据清洗!$J$2:$J$177,"少于每周1天",数据清洗!$CQ$2:$CQ$177,"<>") -> 7 | H14: =IF(G14<5,"",F14/G14) -> 0.85714286 | I14: =COUNTIFS(数据清洗!$E$2:$E$177,1,数据清洗!$J$2:$J$177,"少于每周1天",数据清洗!$CS$2:$CS$177,4)+COUNTIFS(数据清洗!$E$2:$E$177,1,数据清洗!$J$2:$J$177,"少于每周1天",数据清洗!$CS$2:$CS$177,5) -> 6 | J14: =COUNTIFS(数据清洗!$E$2:$E$177,1,数据清洗!$J$2:$J$177,"少于每周1天",数据清洗!$CS$2:$CS$177,"<>") -> 7 | K14: =IF(J14<5,"",I14/J14) -> 0.85714286
A15: B站频率 | B15: 过去3个月没有使用过 | C15: =COUNTIFS(数据清洗!$E$2:$E$177,1,数据清洗!$J$2:$J$177,"过去3个月没有使用过") -> 2 | D15: =COUNTIFS(数据清洗!$E$2:$E$177,1,数据清洗!$J$2:$J$177,"过去3个月没有使用过",数据清洗!$M$2:$M$177,"有") -> 0 | E15: =IF(C15<5,"",D15/C15) | F15: =COUNTIFS(数据清洗!$E$2:$E$177,1,数据清洗!$J$2:$J$177,"过去3个月没有使用过",数据清洗!$CQ$2:$CQ$177,4)+COUNTIFS(数据清洗!$E$2:$E$177,1,数据清洗!$J$2:$J$177,"过去3个月没有使用过",数据清洗!$CQ$2:$CQ$177,5) -> 0 | G15: =COUNTIFS(数据清洗!$E$2:$E$177,1,数据清洗!$J$2:$J$177,"过去3个月没有使用过",数据清洗!$CQ$2:$CQ$177,"<>") -> 0 | H15: =IF(G15<5,"",F15/G15) | I15: =COUNTIFS(数据清洗!$E$2:$E$177,1,数据清洗!$J$2:$J$177,"过去3个月没有使用过",数据清洗!$CS$2:$CS$177,4)+COUNTIFS(数据清洗!$E$2:$E$177,1,数据清洗!$J$2:$J$177,"过去3个月没有使用过",数据清洗!$CS$2:$CS$177,5) -> 0 | J15: =COUNTIFS(数据清洗!$E$2:$E$177,1,数据清洗!$J$2:$J$177,"过去3个月没有使用过",数据清洗!$CS$2:$CS$177,"<>") -> 0 | K15: =IF(J15<5,"",I15/J15)
A16: B站频率 | B16: 从未使用过B站 | C16: =COUNTIFS(数据清洗!$E$2:$E$177,1,数据清洗!$J$2:$J$177,"从未使用过B站") -> 5 | D16: =COUNTIFS(数据清洗!$E$2:$E$177,1,数据清洗!$J$2:$J$177,"从未使用过B站",数据清洗!$M$2:$M$177,"有") -> 2 | E16: =IF(C16<5,"",D16/C16) -> 0.4 | F16: =COUNTIFS(数据清洗!$E$2:$E$177,1,数据清洗!$J$2:$J$177,"从未使用过B站",数据清洗!$CQ$2:$CQ$177,4)+COUNTIFS(数据清洗!$E$2:$E$177,1,数据清洗!$J$2:$J$177,"从未使用过B站",数据清洗!$CQ$2:$CQ$177,5) -> 1 | G16: =COUNTIFS(数据清洗!$E$2:$E$177,1,数据清洗!$J$2:$J$177,"从未使用过B站",数据清洗!$CQ$2:$CQ$177,"<>") -> 1 | H16: =IF(G16<5,"",F16/G16) | I16: =COUNTIFS(数据清洗!$E$2:$E$177,1,数据清洗!$J$2:$J$177,"从未使用过B站",数据清洗!$CS$2:$CS$177,4)+COUNTIFS(数据清洗!$E$2:$E$177,1,数据清洗!$J$2:$J$177,"从未使用过B站",数据清洗!$CS$2:$CS$177,5) -> 0 | J16: =COUNTIFS(数据清洗!$E$2:$E$177,1,数据清洗!$J$2:$J$177,"从未使用过B站",数据清洗!$CS$2:$CS$177,"<>") -> 1 | K16: =IF(J16<5,"",I16/J16)
A17: 交易记录 | B17: 出售尝试记录 | C17: =COUNTIFS(数据清洗!$E$2:$E$177,1,数据清洗!$X$2:$X$177,"出售尝试记录") -> 28 | D17: =COUNTIFS(数据清洗!$E$2:$E$177,1,数据清洗!$X$2:$X$177,"出售尝试记录",数据清洗!$M$2:$M$177,"有") -> 20 | E17: =IF(C17<5,"",D17/C17) -> 0.71428571 | F17: =COUNTIFS(数据清洗!$E$2:$E$177,1,数据清洗!$X$2:$X$177,"出售尝试记录",数据清洗!$CQ$2:$CQ$177,4)+COUNTIFS(数据清洗!$E$2:$E$177,1,数据清洗!$X$2:$X$177,"出售尝试记录",数据清洗!$CQ$2:$CQ$177,5) -> 21 | G17: =COUNTIFS(数据清洗!$E$2:$E$177,1,数据清洗!$X$2:$X$177,"出售尝试记录",数据清洗!$CQ$2:$CQ$177,"<>") -> 23 | H17: =IF(G17<5,"",F17/G17) -> 0.91304348 | I17: =COUNTIFS(数据清洗!$E$2:$E$177,1,数据清洗!$X$2:$X$177,"出售尝试记录",数据清洗!$CS$2:$CS$177,4)+COUNTIFS(数据清洗!$E$2:$E$177,1,数据清洗!$X$2:$X$177,"出售尝试记录",数据清洗!$CS$2:$CS$177,5) -> 11 | J17: =COUNTIFS(数据清洗!$E$2:$E$177,1,数据清洗!$X$2:$X$177,"出售尝试记录",数据清洗!$CS$2:$CS$177,"<>") -> 22 | K17: =IF(J17<5,"",I17/J17) -> 0.5
A18: 交易记录 | B18: 交换尝试记录 | C18: =COUNTIFS(数据清洗!$E$2:$E$177,1,数据清洗!$X$2:$X$177,"交换尝试记录") -> 40 | D18: =COUNTIFS(数据清洗!$E$2:$E$177,1,数据清洗!$X$2:$X$177,"交换尝试记录",数据清洗!$M$2:$M$177,"有") -> 17 | E18: =IF(C18<5,"",D18/C18) -> 0.425 | F18: =COUNTIFS(数据清洗!$E$2:$E$177,1,数据清洗!$X$2:$X$177,"交换尝试记录",数据清洗!$CQ$2:$CQ$177,4)+COUNTIFS(数据清洗!$E$2:$E$177,1,数据清洗!$X$2:$X$177,"交换尝试记录",数据清洗!$CQ$2:$CQ$177,5) -> 23 | G18: =COUNTIFS(数据清洗!$E$2:$E$177,1,数据清洗!$X$2:$X$177,"交换尝试记录",数据清洗!$CQ$2:$CQ$177,"<>") -> 31 | H18: =IF(G18<5,"",F18/G18) -> 0.74193548 | I18: =COUNTIFS(数据清洗!$E$2:$E$177,1,数据清洗!$X$2:$X$177,"交换尝试记录",数据清洗!$CS$2:$CS$177,4)+COUNTIFS(数据清洗!$E$2:$E$177,1,数据清洗!$X$2:$X$177,"交换尝试记录",数据清洗!$CS$2:$CS$177,5) -> 27 | J18: =COUNTIFS(数据清洗!$E$2:$E$177,1,数据清洗!$X$2:$X$177,"交换尝试记录",数据清洗!$CS$2:$CS$177,"<>") -> 36 | K18: =IF(J18<5,"",I18/J18) -> 0.75
A19: 交易记录 | B19: 明确均未尝试 | C19: =COUNTIFS(数据清洗!$E$2:$E$177,1,数据清洗!$X$2:$X$177,"明确均未尝试") -> 41 | D19: =COUNTIFS(数据清洗!$E$2:$E$177,1,数据清洗!$X$2:$X$177,"明确均未尝试",数据清洗!$M$2:$M$177,"有") -> 9 | E19: =IF(C19<5,"",D19/C19) -> 0.2195122 | F19: =COUNTIFS(数据清洗!$E$2:$E$177,1,数据清洗!$X$2:$X$177,"明确均未尝试",数据清洗!$CQ$2:$CQ$177,4)+COUNTIFS(数据清洗!$E$2:$E$177,1,数据清洗!$X$2:$X$177,"明确均未尝试",数据清洗!$CQ$2:$CQ$177,5) -> 1 | G19: =COUNTIFS(数据清洗!$E$2:$E$177,1,数据清洗!$X$2:$X$177,"明确均未尝试",数据清洗!$CQ$2:$CQ$177,"<>") -> 2 | H19: =IF(G19<5,"",F19/G19) | I19: =COUNTIFS(数据清洗!$E$2:$E$177,1,数据清洗!$X$2:$X$177,"明确均未尝试",数据清洗!$CS$2:$CS$177,4)+COUNTIFS(数据清洗!$E$2:$E$177,1,数据清洗!$X$2:$X$177,"明确均未尝试",数据清洗!$CS$2:$CS$177,5) -> 1 | J19: =COUNTIFS(数据清洗!$E$2:$E$177,1,数据清洗!$X$2:$X$177,"明确均未尝试",数据清洗!$CS$2:$CS$177,"<>") -> 2 | K19: =IF(J19<5,"",I19/J19)
A20: 交易记录 | B20: 无法判断 | C20: =COUNTIFS(数据清洗!$E$2:$E$177,1,数据清洗!$X$2:$X$177,"无法判断") -> 13 | D20: =COUNTIFS(数据清洗!$E$2:$E$177,1,数据清洗!$X$2:$X$177,"无法判断",数据清洗!$M$2:$M$177,"有") -> 12 | E20: =IF(C20<5,"",D20/C20) -> 0.92307692 | F20: =COUNTIFS(数据清洗!$E$2:$E$177,1,数据清洗!$X$2:$X$177,"无法判断",数据清洗!$CQ$2:$CQ$177,4)+COUNTIFS(数据清洗!$E$2:$E$177,1,数据清洗!$X$2:$X$177,"无法判断",数据清洗!$CQ$2:$CQ$177,5) -> 2 | G20: =COUNTIFS(数据清洗!$E$2:$E$177,1,数据清洗!$X$2:$X$177,"无法判断",数据清洗!$CQ$2:$CQ$177,"<>") -> 3 | H20: =IF(G20<5,"",F20/G20) | I20: =COUNTIFS(数据清洗!$E$2:$E$177,1,数据清洗!$X$2:$X$177,"无法判断",数据清洗!$CS$2:$CS$177,4)+COUNTIFS(数据清洗!$E$2:$E$177,1,数据清洗!$X$2:$X$177,"无法判断",数据清洗!$CS$2:$CS$177,5) -> 2 | J20: =COUNTIFS(数据清洗!$E$2:$E$177,1,数据清洗!$X$2:$X$177,"无法判断",数据清洗!$CS$2:$CS$177,"<>") -> 3 | K20: =IF(J20<5,"",I20/J20)
A25: 敏感性指标 | B25: 主分析 n | C25: 主分析 N | D25: 主分析比例 | E25: 含异常群 n | F25: 筛选后 N | G25: 对照比例 | H25: 差值 百分点
A26: 近12月买过周边 | B26: =COUNTIFS(数据清洗!$E$2:$E$177,1,数据清洗!$L$2:$L$177,1) -> 94 | C26: =COUNTIFS(数据清洗!$E$2:$E$177,1) -> 122 | D26: =B26/C26 -> 0.7704918 | E26: =COUNTIFS(数据清洗!$D$2:$D$177,1,数据清洗!$L$2:$L$177,1) -> 115 | F26: =COUNTIFS(数据清洗!$D$2:$D$177,1) -> 175 | G26: =E26/F26 -> 0.65714286 | H26: =(D26-G26)*100 -> 11.334895
A27: 有闲置 | B27: =COUNTIFS(数据清洗!$E$2:$E$177,1,数据清洗!$M$2:$M$177,"有") -> 58 | C27: =COUNTIFS(数据清洗!$E$2:$E$177,1) -> 122 | D27: =B27/C27 -> 0.47540984 | E27: =COUNTIFS(数据清洗!$D$2:$D$177,1,数据清洗!$M$2:$M$177,"有") -> 75 | F27: =COUNTIFS(数据清洗!$D$2:$D$177,1) -> 175 | G27: =E27/F27 -> 0.42857143 | H27: =(D27-G27)*100 -> 4.6838407
A29: 对照含53份重复文本群，只检查清洗选择对结论的影响，不作为推荐结论。购买占比差异11.3个百分点；闲置占比差异4.7个百分点。

Sheet 数据清洗
A1: id | B1: source_row | C1: status | D1: eligible | E1: main | F1: duration | G1: age | H1: gender | I1: education | J1: frequency | K1: purchase | L1: purchased | M1: idle | N1: experience | O1: q11_conflict | P1: flags | Q1: repeat_text | R1: same_ip | S1: intent_missing | T1: q18_multi | U1: q14_row_error | V1: q12_type | W1: q12_freq | X1: trade_group | Y1: type_base | Z1: type_1 | AA1: type_2 | AB1: type_3 | AC1: type_4 | AD1: type_5 | AE1: type_6 | AF1: type_7 | AG1: buy_base | AH1: buy_1 | AI1: buy_2 | AJ1: buy_3 | AK1: buy_4 | AL1: buy_5 | AM1: buy_6 | AN1: buy_7 | AO1: buy_8 | AP1: buy_9 | AQ1: disposal_base | AR1: disposal_1 | AS1: disposal_2 | AT1: disposal_3 | AU1: disposal_4 | AV1: disposal_5 | AW1: disposal_6 | AX1: channel_base | AY1: channel_1 | AZ1: channel_2 | BA1: channel_3 | BB1: channel_4 | BC1: channel_5 | BD1: channel_6 | BE1: channel_7 | BF1: channel_8 | BG1: barrier_base | BH1: barrier_1 | BI1: barrier_2 | BJ1: barrier_3 | BK1: barrier_4 | BL1: barrier_5 | BM1: barrier_6 | BN1: barrier_7 | BO1: barrier_8 | BP1: barrier_9 | BQ1: barrier_10 | BR1: barrier_11 | BS1: barrier_12 | BT1: barrier_13 | BU1: concern_base | BV1: concern_1 | BW1: concern_2 | BX1: concern_3 | BY1: concern_4 | BZ1: concern_5 | CA1: concern_6 | CB1: concern_7 | CC1: concern_8 | CD1: concern_9 | CE1: concern_10 | CF1: reason_base | CG1: reason_1 | CH1: reason_2 | CI1: reason_3 | CJ1: reason_4 | CK1: reason_5 | CL1: reason_6 | CM1: reason_7 | CN1: reason_8 | CO1: reason_9 | CP1: reason_10 | CQ1: intent1 | CR1: intent_raw1 | CS1: intent2 | CT1: intent_raw2 | CU1: intent3 | CV1: intent_raw3 | CW1: intent4 | CX1: intent_raw4
A2: 1 | B2: 2 | C2: 主分析 | D2: 1 | E2: 1 | F2: 982 | G2: 30–39岁 | H2: 女 | I2: 硕士研究生及以上 | J2: 从未使用过B站 | K2: 1–2次 | L2: 1 | M2: 有 | N2: 可确认尝试 | O2: 0 | P2: Q14行无法可靠匹配；Q18最主要原因多选 | Q2: 0 | R2: 0 | S2: 0 | T2: 1 | U2: 1 | V2: 与他人交换周边 | W2: 完成1–2次 | X2: 交换尝试记录 | Y2: 1 | Z2: 1 | AA2: 0 | AB2: 0 | AC2: 1 | AD2: 1 | AE2: 1 | AF2: 0 | AG2: 1 | AH2: 0 | AI2: 0 | AJ2: 0 | AK2: 1 | AL2: 0 | AM2: 1 | AN2: 0 | AO2: 0 | AP2: 1 | AQ2: 1 | AR2: 0 | AS2: 0 | AT2: 0 | AU2: 0 | AV2: 0 | AW2: 1 | AX2: 1 | AY2: 0 | AZ2: 0 | BA2: 0 | BB2: 0 | BC2: 0 | BD2: 1 | BE2: 0 | BF2: 1 | BG2: 0 | BU2: 1 | BV2: 0 | BW2: 1 | BX2: 1 | BY2: 0 | BZ2: 0 | CA2: 0 | CB2: 1 | CC2: 1 | CD2: 1 | CE2: 0 | CF2: 0 | CQ2: 5 | CR2: 非常可能 | CS2: 3 | CT2: 不确定 | CU2: 4 | CV2: 比较可能 | CW2: 5 | CX2: 非常可能
A3: 2 | B3: 3 | C3: 主分析 | D3: 1 | E3: 1 | F3: 733 | G3: 23–29岁 | H3: 男 | I3: 本科 | J3: 每周1–2天 | K3: 3–5次 | L3: 1 | M3: 有 | N3: 可确认尝试 | O3: 0 | P3: Q18最主要原因多选；Q16第3项用词歧义；Q16第4项用词歧义 | Q3: 0 | R3: 0 | S3: 0 | T3: 1 | U3: 0 | V3: 出售个人周边 | W3: 完成3–5次 | X3: 出售尝试记录 | Y3: 1 | Z3: 0 | AA3: 0 | AB3: 0 | AC3: 1 | AD3: 1 | AE3: 0 | AF3: 0 | AG3: 1 | AH3: 1 | AI3: 1 | AJ3: 0 | AK3: 0 | AL3: 0 | AM3: 0 | AN3: 0 | AO3: 0 | AP3: 1 | AQ3: 1 | AR3: 1 | AS3: 0 | AT3: 1 | AU3: 1 | AV3: 0 | AW3: 0 | AX3: 1 | AY3: 1 | AZ3: 1 | BA3: 0 | BB3: 0 | BC3: 0 | BD3: 0 | BE3: 0 | BF3: 1 | BG3: 1 | BH3: 0 | BI3: 0 | BJ3: 1 | BK3: 0 | BL3: 0 | BM3: 0 | BN3: 0 | BO3: 1 | BP3: 0 | BQ3: 1 | BR3: 1 | BS3: 0 | BT3: 1 | BU3: 1 | BV3: 1 | BW3: 1 | BX3: 1 | BY3: 0 | BZ3: 0 | CA3: 0 | CB3: 0 | CC3: 1 | CD3: 1 | CE3: 0 | CF3: 0 | CQ3: 3 | CR3: 需要了解 | CS3: 3 | CT3: 需要了解 | CV3: 可能 | CX3: 可能
A4: 3 | B4: 4 | C4: 主分析 | D4: 1 | E4: 1 | F4: 830 | G4: 30–39岁 | H4: 男 | I4: 本科 | J4: 几乎每天 | K4: 3–5次 | L4: 1 | M4: 没有 | N4: 无法判断 | O4: 0 | P4: Q14行无法可靠匹配 | Q4: 0 | R4: 0 | S4: 0 | T4: 0 | U4: 1 | V4: 与他人交换周边 | W4: 没有尝试过 | X4: 无法判断 | Y4: 1 | Z4: 1 | AA4: 0 | AB4: 0 | AC4: 0 | AD4: 1 | AE4: 0 | AF4: 0 | AG4: 1 | AH4: 1 | AI4: 0 | AJ4: 0 | AK4: 0 | AL4: 0 | AM4: 0 | AN4: 0 | AO4: 0 | AP4: 0 | AQ4: 0 | AX4: 0 | BG4: 0 | BU4: 1 | BV4: 0 | BW4: 0 | BX4: 1 | BY4: 0 | BZ4: 0 | CA4: 1 | CB4: 0 | CC4: 0 | CD4: 0 | CE4: 0 | CF4: 1 | CG4: 0 | CH4: 0 | CI4: 0 | CJ4: 1 | CK4: 0 | CL4: 0 | CM4: 0 | CN4: 0 | CO4: 0 | CP4: 0 | CQ4: 4 | CR4: 比较可能 | CS4: 5 | CT4: 非常可能 | CU4: 3 | CV4: 不确定 | CW4: 2 | CX4: 比较不可能
A5: 4 | B5: 5 | C5: 主分析 | D5: 1 | E5: 1 | F5: 330 | G5: 30–39岁 | H5: 男 | I5: 本科 | J5: 每周1–2天 | K5: 1–2次 | L5: 1 | M5: 没有 | N5: 可确认尝试 | O5: 0 | P5: Q18最主要原因多选 | Q5: 0 | R5: 0 | S5: 0 | T5: 1 | U5: 0 | V5: 与他人交换周边 | W5: 完成6次及以上 | X5: 交换尝试记录 | Y5: 1 | Z5: 1 | AA5: 0 | AB5: 1 | AC5: 0 | AD5: 0 | AE5: 1 | AF5: 0 | AG5: 1 | AH5: 0 | AI5: 0 | AJ5: 1 | AK5: 1 | AL5: 0 | AM5: 1 | AN5: 0 | AO5: 0 | AP5: 0 | AQ5: 0 | AX5: 1 | AY5: 1 | AZ5: 0 | BA5: 0 | BB5: 0 | BC5: 1 | BD5: 0 | BE5: 0 | BF5: 0 | BG5: 1 | BH5: 0 | BI5: 0 | BJ5: 0 | BK5: 0 | BL5: 0 | BM5: 0 | BN5: 0 | BO5: 0 | BP5: 1 | BQ5: 1 | BR5: 0 | BS5: 0 | BT5: 1 | BU5: 1 | BV5: 1 | BW5: 1 | BX5: 0 | BY5: 0 | BZ5: 0 | CA5: 0 | CB5: 0 | CC5: 0 | CD5: 0 | CE5: 0 | CF5: 0 | CS5: 4 | CT5: 比较可能 | CU5: 4 | CV5: 比较可能
A6: 5 | B6: 6 | C6: 主分析 | D6: 1 | E6: 1 | F6: 272 | G6: 30–39岁 | H6: 男 | I6: 本科 | J6: 几乎每天 | K6: 0次 | L6: 0 | M6: 没有 | N6: 可确认尝试 | O6: 0 | P6: Q14行无法可靠匹配；Q16第4项用词歧义 | Q6: 0 | R6: 0 | S6: 0 | T6: 0 | U6: 1 | V6: 与他人交换周边 | W6: 完成1–2次 | X6: 交换尝试记录 | Y6: 0 | AG6: 0 | AQ6: 0 | AX6: 1 | AY6: 0 | AZ6: 1 | BA6: 0 | BB6: 0 | BC6: 0 | BD6: 0 | BE6: 0 | BF6: 0 | BG6: 0 | BU6: 1 | BV6: 0 | BW6: 1 | BX6: 0 | BY6: 0 | BZ6: 0 | CA6: 0 | CB6: 0 | CC6: 1 | CD6: 0 | CE6: 0 | CF6: 1 | CG6: 0 | CH6: 0 | CI6: 0 | CJ6: 0 | CK6: 0 | CL6: 0 | CM6: 1 | CN6: 0 | CO6: 0 | CP6: 0 | CQ6: 3 | CR6: 不确定 | CS6: 4 | CT6: 比较可能 | CU6: 3 | CV6: 不确定 | CX6: 可能
A7: 6 | B7: 7 | C7: 主分析 | D7: 1 | E7: 1 | F7: 697 | G7: 23–29岁 | H7: 女 | I7: 本科 | J7: 每周1–2天 | K7: 3–5次 | L7: 1 | M7: 有 | N7: 可确认尝试 | O7: 0 | P7: Q14行无法可靠匹配；Q18最主要原因多选 | Q7: 0 | R7: 0 | S7: 0 | T7: 1 | U7: 1 | V7: 与他人交换周边 | W7: 完成1–2次 | X7: 交换尝试记录 | Y7: 1 | Z7: 1 | AA7: 0 | AB7: 0 | AC7: 0 | AD7: 1 | AE7: 1 | AF7: 0 | AG7: 1 | AH7: 1 | AI7: 0 | AJ7: 1 | AK7: 0 | AL7: 0 | AM7: 1 | AN7: 1 | AO7: 0 | AP7: 0 | AQ7: 1 | AR7: 0 | AS7: 0 | AT7: 1 | AU7: 1 | AV7: 0 | AW7: 1 | AX7: 1 | AY7: 1 | AZ7: 1 | BA7: 1 | BB7: 0 | BC7: 1 | BD7: 0 | BE7: 0 | BF7: 0 | BG7: 0 | BU7: 1 | BV7: 0 | BW7: 1 | BX7: 0 | BY7: 0 | BZ7: 0 | CA7: 0 | CB7: 0 | CC7: 1 | CD7: 1 | CE7: 0 | CF7: 0 | CQ7: 3 | CR7: 不确定/需要了解更多规则 | CS7: 2 | CT7: 比较不可能 | CU7: 4 | CV7: 比较可能 | CW7: 97 | CX7: 不适用：没有对应需求或条件
A8: 7 | B8: 8 | C8: 主分析 | D8: 1 | E8: 1 | F8: 309 | G8: 18–22岁 | H8: 其他 | I8: 大专 | J8: 少于每周1天 | K8: 3–5次 | L8: 1 | M8: 不确定 | N8: 可确认尝试 | O8: 0 | P8: Q14行无法可靠匹配；Q18最主要原因多选 | Q8: 0 | R8: 0 | S8: 0 | T8: 1 | U8: 1 | V8: 与他人交换周边 | W8: 完成3–5次 | X8: 交换尝试记录 | Y8: 1 | Z8: 0 | AA8: 0 | AB8: 1 | AC8: 0 | AD8: 0 | AE8: 1 | AF8: 0 | AG8: 1 | AH8: 0 | AI8: 0 | AJ8: 0 | AK8: 1 | AL8: 0 | AM8: 1 | AN8: 1 | AO8: 0 | AP8: 0 | AQ8: 0 | AX8: 1 | AY8: 0 | AZ8: 1 | BA8: 0 | BB8: 0 | BC8: 0 | BD8: 1 | BE8: 0 | BF8: 0 | BG8: 0 | BU8: 1 | BV8: 0 | BW8: 0 | BX8: 0 | BY8: 0 | BZ8: 0 | CA8: 0 | CB8: 0 | CC8: 0 | CD8: 0 | CE8: 1 | CF8: 0 | CQ8: 97 | CR8: 不适用 | CS8: 4 | CT8: 比较可能 | CU8: 4 | CV8: 比较可能 | CW8: 4 | CX8: 比较可能
A9: 8 | B9: 9 | C9: 主分析 | D9: 1 | E9: 1 | F9: 580 | G9: 23–29岁 | H9: 女 | I9: 大专 | J9: 每周1–2天 | K9: 3–5次 | L9: 1 | M9: 有 | N9: 可确认尝试 | O9: 0 | P9: Q14行无法可靠匹配；Q18最主要原因多选 | Q9: 0 | R9: 0 | S9: 0 | T9: 1 | U9: 1 | V9: 出售个人周边 | W9: 完成1–2次 | X9: 出售尝试记录 | Y9: 1 | Z9: 1 | AA9: 0 | AB9: 1 | AC9: 0 | AD9: 0 | AE9: 0 | AF9: 0 | AG9: 1 | AH9: 0 | AI9: 1 | AJ9: 0 | AK9: 1 | AL9: 0 | AM9: 1 | AN9: 0 | AO9: 0 | AP9: 0 | AQ9: 1 | AR9: 1 | AS9: 0 | AT9: 1 | AU9: 0 | AV9: 1 | AW9: 0 | AX9: 1 | AY9: 0 | AZ9: 1 | BA9: 0 | BB9: 0 | BC9: 1 | BD9: 1 | BE9: 0 | BF9: 0 | BG9: 0 | BU9: 1 | BV9: 0 | BW9: 0 | BX9: 0 | BY9: 0 | BZ9: 0 | CA9: 1 | CB9: 1 | CC9: 0 | CD9: 0 | CE9: 0 | CF9: 0 | CQ9: 5 | CR9: 非常可能 | CS9: 4 | CT9: 比较可能 | CU9: 5 | CV9: 非常可能 | CW9: 3 | CX9: 不确定
A10: 9 | B10: 10 | C10: 主分析 | D10: 1 | E10: 1 | F10: 418 | G10: 23–29岁 | H10: 男 | I10: 本科 | J10: 每周1–2天 | K10: 3–5次 | L10: 1 | M10: 有 | N10: 可确认尝试 | O10: 0 | P10: Q14行无法可靠匹配；Q18最主要原因多选；Q16第4项用词歧义 | Q10: 0 | R10: 0 | S10: 0 | T10: 1 | U10: 1 | V10: 与他人交换周边 | W10: 完成3–5次 | X10: 交换尝试记录 | Y10: 1 | Z10: 0 | AA10: 0 | AB10: 0 | AC10: 1 | AD10: 1 | AE10: 1 | AF10: 0 | AG10: 1 | AH10: 1 | AI10: 0 | AJ10: 0 | AK10: 0 | AL10: 0 | AM10: 1 | AN10: 0 | AO10: 0 | AP10: 1 | AQ10: 1 | AR10: 0 | AS10: 0 | AT10: 1 | AU10: 1 | AV10: 1 | AW10: 1 | AX10: 1 | AY10: 1 | AZ10: 1 | BA10: 0 | BB10: 0 | BC10: 1 | BD10: 0 | BE10: 0 | BF10: 1 | BG10: 0 | BU10: 1 | BV10: 1 | BW10: 1 | BX10: 1 | BY10: 0 | BZ10: 0 | CA10: 0 | CB10: 0 | CC10: 0 | CD10: 0 | CE10: 0 | CF10: 0 | CQ10: 4 | CR10: 比较可能 | CS10: 4 | CT10: 比较可能 | CU10: 3 | CV10: 不确定 | CX10: 非常可爱
A11: 10 | B11: 11 | C11: 主分析 | D11: 1 | E11: 1 | F11: 222 | G11: 23–29岁 | H11: 男 | I11: 本科 | J11: 少于每周1天 | K11: 6–11次 | L11: 1 | M11: 没有 | N11: 可确认尝试 | O11: 0 | P11: 未触发已设检查（不代表真实性已验证） | Q11: 0 | R11: 0 | S11: 0 | T11: 0 | U11: 0 | V11: 与他人交换周边 | W11: 完成3–5次 | X11: 交换尝试记录 | Y11: 1 | Z11: 0 | AA11: 0 | AB11: 0 | AC11: 0 | AD11: 1 | AE11: 0 | AF11: 0 | AG11: 1 | AH11: 0 | AI11: 0 | AJ11: 0 | AK11: 0 | AL11: 0 | AM11: 1 | AN11: 0 | AO11: 0 | AP11: 0 | AQ11: 0 | AX11: 1 | AY11: 0 | AZ11: 0 | BA11: 0 | BB11: 0 | BC11: 0 | BD11: 0 | BE11: 0 | BF11: 1 | BG11: 1 | BH11: 0 | BI11: 0 | BJ11: 0 | BK11: 1 | BL11: 0 | BM11: 0 | BN11: 1 | BO11: 0 | BP11: 0 | BQ11: 0 | BR11: 0 | BS11: 0 | BT11: 0 | BU11: 1 | BV11: 0 | BW11: 1 | BX11: 0 | BY11: 0 | BZ11: 0 | CA11: 0 | CB11: 0 | CC11: 1 | CD11: 1 | CE11: 0 | CF11: 1 | CG11: 0 | CH11: 0 | CI11: 0 | CJ11: 0 | CK11: 0 | CL11: 0 | CM11: 0 | CN11: 1 | CO11: 0 | CP11: 0 | CQ11: 5 | CR11: 非常可能 | CS11: 4 | CT11: 比较可能 | CU11: 4 | CV11: 比较可能 | CW11: 5 | CX11: 非常可能
A12: 11 | B12: 12 | C12: 质量暂不纳入 | D12: 1 | E12: 0 | F12: 268 | G12: 30–39岁 | H12: 女 | I12: 本科 | J12: 每周3–6天 | K12: 0次 | L12: 0 | M12: 没有 | N12: 可确认尝试 | O12: 0 | P12: Q15五填空整段跨记录重复，主分析暂不纳入；Q16无可能性填写；Q14行无法可靠匹配；Q18最主要原因多选；concern互斥混选 | Q12: 1 | R12: 0 | S12: 1 | T12: 1 | U12: 1 | V12: 出售个人周边 | W12: 完成1–2次 | X12: 出售尝试记录 | Y12: 0 | AG12: 0 | AQ12: 0 | AX12: 1 | AY12: 1 | AZ12: 0 | BA12: 0 | BB12: 0 | BC12: 0 | BD12: 0 | BE12: 0 | BF12: 1 | BG12: 0 | BU12: 0 | CF12: 0
A13: 12 | B13: 13 | C13: 主分析 | D13: 1 | E13: 1 | F13: 309 | G13: 23–29岁 | H13: 男 | I13: 本科 | J13: 每周1–2天 | K13: 6–11次 | L13: 1 | M13: 有 | N13: 可确认尝试 | O13: 0 | P13: Q14行无法可靠匹配；Q18最主要原因多选 | Q13: 0 | R13: 0 | S13: 0 | T13: 1 | U13: 1 | V13: 与他人交换周边 | W13: 尝试过，但未完成 | X13: 交换尝试记录 | Y13: 1 | Z13: 0 | AA13: 0 | AB13: 1 | AC13: 1 | AD13: 1 | AE13: 0 | AF13: 0 | AG13: 1 | AH13: 0 | AI13: 0 | AJ13: 1 | AK13: 1 | AL13: 0 | AM13: 0 | AN13: 1 | AO13: 0 | AP13: 0 | AQ13: 1 | AR13: 0 | AS13: 0 | AT13: 1 | AU13: 1 | AV13: 1 | AW13: 0 | AX13: 1 | AY13: 1 | AZ13: 1 | BA13: 0 | BB13: 0 | BC13: 0 | BD13: 0 | BE13: 0 | BF13: 1 | BG13: 0 | BU13: 1 | BV13: 1 | BW13: 1 | BX13: 1 | BY13: 0 | BZ13: 0 | CA13: 0 | CB13: 0 | CC13: 0 | CD13: 0 | CE13: 0 | CF13: 0 | CQ13: 3 | CR13: 不确定 | CS13: 2 | CT13: 比较不可能 | CU13: 4 | CV13: 比较可能 | CW13: 5 | CX13: 非常可能
A14: 13 | B14: 14 | C14: 质量暂不纳入 | D14: 1 | E14: 0 | F14: 274 | G14: 23–29岁 | H14: 男 | I14: 本科 | J14: 每周3–6天 | K14: 0次 | L14: 0 | M14: 不确定 | N14: 无法判断 | O14: 0 | P14: Q15五填空整段跨记录重复，主分析暂不纳入；Q16无可能性填写；Q14行无法可靠匹配；Q18最主要原因多选 | Q14: 1 | R14: 0 | S14: 1 | T14: 1 | U14: 1 | V14: 与他人交换周边 | W14: 没有尝试过 | X14: 无法判断 | Y14: 0 | AG14: 0 | AQ14: 0 | AX14: 0 | BG14: 0 | BU14: 1 | BV14: 1 | BW14: 1 | BX14: 0 | BY14: 0 | BZ14: 0 | CA14: 0 | CB14: 1 | CC14: 0 | CD14: 0 | CE14: 0 | CF14: 0
A15: 14 | B15: 15 | C15: 主分析 | D15: 1 | E15: 1 | F15: 295 | G15: 23–29岁 | H15: 男 | I15: 本科 | J15: 每周3–6天 | K15: 0次 | L15: 0 | M15: 没有 | N15: 明确均未尝试 | O15: 0 | P15: Q16无可能性填写 | Q15: 0 | R15: 0 | S15: 1 | T15: 0 | U15: 0 | V15: 均没有尝试过 | W15: (跳过) | X15: 明确均未尝试 | Y15: 0 | AG15: 0 | AQ15: 0 | AX15: 0 | BG15: 0 | BU15: 1 | BV15: 0 | BW15: 0 | BX15: 1 | BY15: 0 | BZ15: 0 | CA15: 0 | CB15: 0 | CC15: 0 | CD15: 0 | CE15: 0 | CF15: 1 | CG15: 1 | CH15: 0 | CI15: 0 | CJ15: 0 | CK15: 0 | CL15: 0 | CM15: 0 | CN15: 0 | CO15: 0 | CP15: 0
A16: 15 | B16: 16 | C16: 主分析 | D16: 1 | E16: 1 | F16: 274 | G16: 18–22岁 | H16: 女 | I16: 本科 | J16: 少于每周1天 | K16: 1–2次 | L16: 1 | M16: 不确定 | N16: 明确均未尝试 | O16: 0 | P16: Q16无可能性填写 | Q16: 0 | R16: 0 | S16: 1 | T16: 0 | U16: 0 | V16: 均没有尝试过 | W16: (跳过) | X16: 明确均未尝试 | Y16: 1 | Z16: 0 | AA16: 0 | AB16: 1 | AC16: 1 | AD16: 1 | AE16: 0 | AF16: 0 | AG16: 1 | AH16: 0 | AI16: 1 | AJ16: 0 | AK16: 0 | AL16: 0 | AM16: 0 | AN16: 0 | AO16: 0 | AP16: 1 | AQ16: 0 | AX16: 0 | BG16: 0 | BU16: 1 | BV16: 1 | BW16: 0 | BX16: 0 | BY16: 0 | BZ16: 0 | CA16: 0 | CB16: 0 | CC16: 0 | CD16: 1 | CE16: 0 | CF16: 1 | CG16: 0 | CH16: 0 | CI16: 0 | CJ16: 0 | CK16: 0 | CL16: 0 | CM16: 0 | CN16: 0 | CO16: 1 | CP16: 0
A17: 16 | B17: 17 | C17: 主分析 | D17: 1 | E17: 1 | F17: 240 | G17: 30–39岁 | H17: 不愿透露 | I17: 本科 | J17: 每周3–6天 | K17: 1–2次 | L17: 1 | M17: 不确定 | N17: 明确均未尝试 | O17: 0 | P17: Q16无可能性填写 | Q17: 0 | R17: 0 | S17: 1 | T17: 0 | U17: 0 | V17: 均没有尝试过 | W17: (跳过) | X17: 明确均未尝试 | Y17: 1 | Z17: 0 | AA17: 0 | AB17: 0 | AC17: 1 | AD17: 0 | AE17: 0 | AF17: 0 | AG17: 1 | AH17: 0 | AI17: 1 | AJ17: 0 | AK17: 0 | AL17: 0 | AM17: 0 | AN17: 0 | AO17: 0 | AP17: 1 | AQ17: 0 | AX17: 0 | BG17: 0 | BU17: 1 | BV17: 0 | BW17: 0 | BX17: 0 | BY17: 0 | BZ17: 0 | CA17: 0 | CB17: 0 | CC17: 0 | CD17: 1 | CE17: 0 | CF17: 1 | CG17: 0 | CH17: 0 | CI17: 0 | CJ17: 0 | CK17: 1 | CL17: 0 | CM17: 0 | CN17: 0 | CO17: 0 | CP17: 0
A18: 17 | B18: 18 | C18: 主分析 | D18: 1 | E18: 1 | F18: 152 | G18: 30–39岁 | H18: 女 | I18: 本科 | J18: 每周1–2天 | K18: 0次 | L18: 0 | M18: 有 | N18: 无法判断 | O18: 1 | P18: Q11尝试与Q12均未尝试冲突；Q16无可能性填写 | Q18: 0 | R18: 0 | S18: 1 | T18: 0 | U18: 0 | V18: 均没有尝试过 | W18: (跳过) | X18: 无法判断 | Y18: 0 | AG18: 0 | AQ18: 0 | AX18: 0 | BG18: 0 | BU18: 1 | BV18: 0 | BW18: 0 | BX18: 0 | BY18: 0 | BZ18: 0 | CA18: 0 | CB18: 0 | CC18: 1 | CD18: 0 | CE18: 0 | CF18: 1 | CG18: 0 | CH18: 0 | CI18: 1 | CJ18: 0 | CK18: 0 | CL18: 0 | CM18: 0 | CN18: 0 | CO18: 0 | CP18: 0
A19: 18 | B19: 19 | C19: 主分析 | D19: 1 | E19: 1 | F19: 128 | G19: 30–39岁 | H19: 男 | I19: 不愿透露 | J19: 每周3–6天 | K19: 0次 | L19: 0 | M19: 有 | N19: 无法判断 | O19: 1 | P19: Q11尝试与Q12均未尝试冲突；Q16无可能性填写；Q18最主要原因多选 | Q19: 0 | R19: 0 | S19: 1 | T19: 1 | U19: 0 | V19: 均没有尝试过 | W19: (跳过) | X19: 无法判断 | Y19: 0 | AG19: 0 | AQ19: 0 | AX19: 0 | BG19: 0 | BU19: 1 | BV19: 0 | BW19: 0 | BX19: 1 | BY19: 0 | BZ19: 0 | CA19: 0 | CB19: 1 | CC19: 0 | CD19: 0 | CE19: 0 | CF19: 0
